<robot name="onshape">
<link name="trunk_1">
<inertial>
<origin xyz="0 0 0" rpy="0 0 0" />
<mass value="1e-9" />
<inertia ixx="0" ixy="0" ixz="0" iyy="0" iyz="0" izz="0" />
</inertial>
</link>
<link name="trunk_1_0_piano_wire_back_fixation">
<inertial>
<origin xyz="0.00664685 0.00830315 0.00277132" rpy="0 0 0"/>
<mass value="0.00242365"/>
<inertia ixx="5.11774e-08" ixy="-1.06263e-08"  ixz="-4.74489e-10" iyy="5.11774e-08" iyz="4.74489e-10" izz="8.85098e-08" />
</inertial>
</link>
<joint name="trunk_1_trunk_1_0_piano_wire_back_fixation_fixing" type="fixed">
<origin xyz="0.06695 0.05195 0.1459" rpy="3.14159 -5.37713e-17 -3.14159" />
<parent link="trunk_1" />
<child link="trunk_1_0_piano_wire_back_fixation" />
<axis xyz="0 0 0"/>
</joint>

<link name="trunk_1_1_dxlboard">
<inertial>
<origin xyz="2.1334e-19 3.99492e-05 0.00075" rpy="0 0 0"/>
<mass value="0.00586342"/>
<inertia ixx="1.31705e-06" ixy="0"  ixz="0" iyy="2.50476e-06" iyz="0" izz="3.81961e-06" />
</inertial>
</link>
<joint name="trunk_1_trunk_1_1_dxlboard_fixing" type="fixed">
<origin xyz="1.03251e-14 -0.015 0.1274" rpy="-1.87755e-18 -5.37713e-17 -3.14159" />
<parent link="trunk_1" />
<child link="trunk_1_1_dxlboard" />
<axis xyz="0 0 0"/>
</joint>

<link name="trunk_1_2_high_leg_protection_right">
<inertial>
<origin xyz="0.0161684 0.0119477 0.00239546" rpy="0 0 0"/>
<mass value="0.011857"/>
<inertia ixx="1.47286e-06" ixy="-2.66485e-07"  ixz="-1.08164e-08" iyy="1.93671e-06" iyz="4.55684e-08" izz="3.33718e-06" />
</inertial>
</link>
<joint name="trunk_1_trunk_1_2_high_leg_protection_right_fixing" type="fixed">
<origin xyz="0.031275 -0.053727 -0.0035" rpy="1.87755e-18 5.37713e-17 -4.24507e-13" />
<parent link="trunk_1" />
<child link="trunk_1_2_high_leg_protection_right" />
<axis xyz="0 0 0"/>
</joint>

<link name="trunk_1_3_lipo_4s_2800mah">
<inertial>
<origin xyz="0.000784961 4.11604e-19 0.0188" rpy="0 0 0"/>
<mass value="0.0729744"/>
<inertia ixx="1.50742e-05" ixy="0"  ixz="0" iyy="8.10311e-05" iyz="1.12948e-11" izz="7.94138e-05" />
</inertial>
</link>
<joint name="trunk_1_trunk_1_3_lipo_4s_2800mah_fixing" type="fixed">
<origin xyz="0.001 0.02375 0.0406" rpy="3.14159 -0 0" />
<parent link="trunk_1" />
<child link="trunk_1_3_lipo_4s_2800mah" />
<axis xyz="0 0 0"/>
</joint>

<link name="trunk_1_4_pillar_tube">
<collision>
<origin xyz="0 0 0.043" rpy="0 -0 0" />
<geometry>
<cylinder length="0.086" radius="0.004" />
</geometry>
<material name="trunk_1_4_pillar_tube_material">
<color rgba="0.501961 0.486275 0.439216 1.0"/>
</material>
</collision>
<visual>
<origin xyz="0 0 0.043" rpy="0 -0 0" />
<geometry>
<cylinder length="0.086" radius="0.004" />
</geometry>
<material name="trunk_1_4_pillar_tube_material">
<color rgba="0.501961 0.486275 0.439216 1.0"/>
</material>
</visual>
<inertial>
<origin xyz="1.97891e-19 3.23657e-19 0.043" rpy="0 0 0"/>
<mass value="0.0148462"/>
<inertia ixx="9.24301e-06" ixy="0"  ixz="0" iyy="9.24301e-06" iyz="0" izz="1.85578e-07" />
</inertial>
</link>
<joint name="trunk_1_trunk_1_4_pillar_tube_fixing" type="fixed">
<origin xyz="-0.031 -0.0535 0.0478999" rpy="1.87755e-18 5.37713e-17 8.68431e-14" />
<parent link="trunk_1" />
<child link="trunk_1_4_pillar_tube" />
<axis xyz="0 0 0"/>
</joint>

<link name="trunk_1_5_mx64">
<collision>
<origin xyz="0 -0.015 0" rpy="0 -0 0" />
<geometry>
<box size="0.029 0.05 0.04" />
</geometry>
<material name="trunk_1_5_mx64_material">
<color rgba="0.211765 0.211765 0.211765 1.0"/>
</material>
</collision>
<visual>
<origin xyz="0 -0.015 0" rpy="0 -0 0" />
<geometry>
<box size="0.029 0.05 0.04" />
</geometry>
<material name="trunk_1_5_mx64_material">
<color rgba="0.211765 0.211765 0.211765 1.0"/>
</material>
</visual>
<inertial>
<origin xyz="0 0 0.00254" rpy="0 0 0"/>
<mass value="0.158"/>
<inertia ixx="7.869e-05" ixy="-8.4e-07"  ixz="4.9e-07" iyy="4.097e-05" iyz="-9.14e-06" izz="6.136e-05" />
</inertial>
</link>
<joint name="trunk_1_trunk_1_5_mx64_fixing" type="fixed">
<origin xyz="-0.046375 -0.010627 0.02" rpy="3.14159 -5.37713e-17 -3.14159" />
<parent link="trunk_1" />
<child link="trunk_1_5_mx64" />
<axis xyz="0 0 0"/>
</joint>

<link name="trunk_1_6_mx64">
<collision>
<origin xyz="0 -0.015 0" rpy="0 -0 0" />
<geometry>
<box size="0.029 0.05 0.04" />
</geometry>
<material name="trunk_1_6_mx64_material">
<color rgba="0.211765 0.211765 0.211765 1.0"/>
</material>
</collision>
<visual>
<origin xyz="0 -0.015 0" rpy="0 -0 0" />
<geometry>
<box size="0.029 0.05 0.04" />
</geometry>
<material name="trunk_1_6_mx64_material">
<color rgba="0.211765 0.211765 0.211765 1.0"/>
</material>
</visual>
<inertial>
<origin xyz="0 0 0.00254" rpy="0 0 0"/>
<mass value="0.158"/>
<inertia ixx="7.869e-05" ixy="-8.4e-07"  ixz="4.9e-07" iyy="4.097e-05" iyz="-9.14e-06" izz="6.136e-05" />
</inertial>
</link>
<joint name="trunk_1_trunk_1_6_mx64_fixing" type="fixed">
<origin xyz="0.05 -0.0315 0.1609" rpy="-3.14159 -1.5708 0" />
<parent link="trunk_1" />
<child link="trunk_1_6_mx64" />
<axis xyz="0 0 0"/>
</joint>

<link name="trunk_1_7_mx64">
<collision>
<origin xyz="0 -0.015 0" rpy="0 -0 0" />
<geometry>
<box size="0.029 0.05 0.04" />
</geometry>
<material name="trunk_1_7_mx64_material">
<color rgba="0.211765 0.211765 0.211765 1.0"/>
</material>
</collision>
<visual>
<origin xyz="0 -0.015 0" rpy="0 -0 0" />
<geometry>
<box size="0.029 0.05 0.04" />
</geometry>
<material name="trunk_1_7_mx64_material">
<color rgba="0.211765 0.211765 0.211765 1.0"/>
</material>
</visual>
<inertial>
<origin xyz="0 0 0.00254" rpy="0 0 0"/>
<mass value="0.158"/>
<inertia ixx="7.869e-05" ixy="-8.4e-07"  ixz="4.9e-07" iyy="4.097e-05" iyz="-9.14e-06" izz="6.136e-05" />
</inertial>
</link>
<joint name="trunk_1_trunk_1_7_mx64_fixing" type="fixed">
<origin xyz="0.046375 -0.010627 0.02" rpy="3.14159 -5.37713e-17 -3.14159" />
<parent link="trunk_1" />
<child link="trunk_1_7_mx64" />
<axis xyz="0 0 0"/>
</joint>

<link name="trunk_1_8_handle">
<collision>
<origin xyz="-0.045 0 0.0015" rpy="0 -0 0" />
<geometry>
<box size="0.01 0.13 0.003" />
</geometry>
<material name="trunk_1_8_handle_material">
<color rgba="0.701961 0.682353 0.623529 1.0"/>
</material>
</collision>
<collision>
<origin xyz="-0.02 -0.06 0.0015" rpy="0 -0 0" />
<geometry>
<box size="0.04 0.01 0.003" />
</geometry>
<material name="trunk_1_8_handle_material">
<color rgba="0.701961 0.682353 0.623529 1.0"/>
</material>
</collision>
<collision>
<origin xyz="-0.02 0.06 0.0015" rpy="0 -0 0" />
<geometry>
<box size="0.04 0.01 0.003" />
</geometry>
<material name="trunk_1_8_handle_material">
<color rgba="0.701961 0.682353 0.623529 1.0"/>
</material>
</collision>
<visual>
<origin xyz="-0.045 0 0.0015" rpy="0 -0 0" />
<geometry>
<box size="0.01 0.13 0.003" />
</geometry>
<material name="trunk_1_8_handle_material">
<color rgba="0.701961 0.682353 0.623529 1.0"/>
</material>
</visual>
<visual>
<origin xyz="-0.02 -0.06 0.0015" rpy="0 -0 0" />
<geometry>
<box size="0.04 0.01 0.003" />
</geometry>
<material name="trunk_1_8_handle_material">
<color rgba="0.701961 0.682353 0.623529 1.0"/>
</material>
</visual>
<visual>
<origin xyz="-0.02 0.06 0.0015" rpy="0 -0 0" />
<geometry>
<box size="0.04 0.01 0.003" />
</geometry>
<material name="trunk_1_8_handle_material">
<color rgba="0.701961 0.682353 0.623529 1.0"/>
</material>
</visual>
<inertial>
<origin xyz="-0.036261 -4.65848e-17 0.0015" rpy="0 0 0"/>
<mass value="0.0137229"/>
<inertia ixx="3.52972e-05" ixy="0"  ixz="0" iyy="2.82078e-06" iyz="0" izz="3.80974e-05" />
</inertial>
</link>
<joint name="trunk_1_trunk_1_8_handle_fixing" type="fixed">
<origin xyz="2.59515e-15 0.07345 0.1449" rpy="1.5708 1.5708 0" />
<parent link="trunk_1" />
<child link="trunk_1_8_handle" />
<axis xyz="0 0 0"/>
</joint>

<link name="trunk_1_9_pillar_tube">
<collision>
<origin xyz="0 0 0.043" rpy="0 -0 0" />
<geometry>
<cylinder length="0.086" radius="0.004" />
</geometry>
<material name="trunk_1_9_pillar_tube_material">
<color rgba="0.501961 0.486275 0.439216 1.0"/>
</material>
</collision>
<visual>
<origin xyz="0 0 0.043" rpy="0 -0 0" />
<geometry>
<cylinder length="0.086" radius="0.004" />
</geometry>
<material name="trunk_1_9_pillar_tube_material">
<color rgba="0.501961 0.486275 0.439216 1.0"/>
</material>
</visual>
<inertial>
<origin xyz="1.97891e-19 3.23657e-19 0.043" rpy="0 0 0"/>
<mass value="0.0148462"/>
<inertia ixx="9.24301e-06" ixy="0"  ixz="0" iyy="9.24301e-06" iyz="0" izz="1.85578e-07" />
</inertial>
</link>
<joint name="trunk_1_trunk_1_9_pillar_tube_fixing" type="fixed">
<origin xyz="0.0625 0.0385 0.1339" rpy="-3.14159 5.37713e-17 8.68292e-14" />
<parent link="trunk_1" />
<child link="trunk_1_9_pillar_tube" />
<axis xyz="0 0 0"/>
</joint>

<link name="trunk_1_10_torso_bottom_plate_nuc">
<collision>
<origin xyz="0.0675 0.023 0.0015" rpy="0 -0 0" />
<geometry>
<box size="0.13 0.044 0.003" />
</geometry>
<material name="trunk_1_10_torso_bottom_plate_nuc_material">
<color rgba="0.301961 0.301961 0.301961 1.0"/>
</material>
</collision>
<collision>
<origin xyz="0.041 -0.016 0.0015" rpy="0 -0 0" />
<geometry>
<box size="0.01 0.035 0.003" />
</geometry>
<material name="trunk_1_10_torso_bottom_plate_nuc_material">
<color rgba="0.301961 0.301961 0.301961 1.0"/>
</material>
</collision>
<collision>
<origin xyz="0.092 -0.016 0.0015" rpy="0 -0 0" />
<geometry>
<box size="0.01 0.035 0.003" />
</geometry>
<material name="trunk_1_10_torso_bottom_plate_nuc_material">
<color rgba="0.301961 0.301961 0.301961 1.0"/>
</material>
</collision>
<visual>
<origin xyz="0.0675 0.023 0.0015" rpy="0 -0 0" />
<geometry>
<box size="0.13 0.044 0.003" />
</geometry>
<material name="trunk_1_10_torso_bottom_plate_nuc_material">
<color rgba="0.301961 0.301961 0.301961 1.0"/>
</material>
</visual>
<visual>
<origin xyz="0.041 -0.016 0.0015" rpy="0 -0 0" />
<geometry>
<box size="0.01 0.035 0.003" />
</geometry>
<material name="trunk_1_10_torso_bottom_plate_nuc_material">
<color rgba="0.301961 0.301961 0.301961 1.0"/>
</material>
</visual>
<visual>
<origin xyz="0.092 -0.016 0.0015" rpy="0 -0 0" />
<geometry>
<box size="0.01 0.035 0.003" />
</geometry>
<material name="trunk_1_10_torso_bottom_plate_nuc_material">
<color rgba="0.301961 0.301961 0.301961 1.0"/>
</material>
</visual>
<inertial>
<origin xyz="0.0664224 0.0172567 0.0015" rpy="0 0 0"/>
<mass value="0.0561286"/>
<inertia ixx="1.83519e-05" ixy="5.54698e-08"  ixz="0" iyy="7.39803e-05" iyz="0" izz="9.2248e-05" />
</inertial>
</link>
<joint name="trunk_1_trunk_1_10_torso_bottom_plate_nuc_fixing" type="fixed">
<origin xyz="-0.0665 0.0035 0" rpy="1.87755e-18 5.37713e-17 8.97971e-16" />
<parent link="trunk_1" />
<child link="trunk_1_10_torso_bottom_plate_nuc" />
<axis xyz="0 0 0"/>
</joint>

<link name="trunk_1_11_mx64">
<collision>
<origin xyz="0 -0.015 0" rpy="0 -0 0" />
<geometry>
<box size="0.029 0.05 0.04" />
</geometry>
<material name="trunk_1_11_mx64_material">
<color rgba="0.211765 0.211765 0.211765 1.0"/>
</material>
</collision>
<visual>
<origin xyz="0 -0.015 0" rpy="0 -0 0" />
<geometry>
<box size="0.029 0.05 0.04" />
</geometry>
<material name="trunk_1_11_mx64_material">
<color rgba="0.211765 0.211765 0.211765 1.0"/>
</material>
</visual>
<inertial>
<origin xyz="0 0 0.00254" rpy="0 0 0"/>
<mass value="0.158"/>
<inertia ixx="7.869e-05" ixy="-8.4e-07"  ixz="4.9e-07" iyy="4.097e-05" iyz="-9.14e-06" izz="6.136e-05" />
</inertial>
</link>
<joint name="trunk_1_trunk_1_11_mx64_fixing" type="fixed">
<origin xyz="-0.0505868 -0.0315 0.1609" rpy="3.14159 1.5708 0" />
<parent link="trunk_1" />
<child link="trunk_1_11_mx64" />
<axis xyz="0 0 0"/>
</joint>

<link name="trunk_1_12_hotswap">
<inertial>
<origin xyz="0.0352561 -8.60613e-06 0.0072072" rpy="0 0 0"/>
<mass value="0.0181451"/>
<inertia ixx="1.96512e-06" ixy="-4.72477e-09"  ixz="-1.14166e-06" iyy="9.34906e-06" iyz="-1.00835e-09" izz="1.036e-05" />
</inertial>
</link>
<joint name="trunk_1_trunk_1_12_hotswap_fixing" type="fixed">
<origin xyz="-0.005 -0.010627 0.0533999" rpy="1.87755e-18 5.37713e-17 8.68376e-14" />
<parent link="trunk_1" />
<child link="trunk_1_12_hotswap" />
<axis xyz="0 0 0"/>
</joint>

<link name="trunk_1_13_high_leg_protection_left">
<inertial>
<origin xyz="0.0742316 0.0119477 0.00239546" rpy="0 0 0"/>
<mass value="0.011857"/>
<inertia ixx="1.47286e-06" ixy="2.66485e-07"  ixz="1.08164e-08" iyy="1.93671e-06" iyz="4.55684e-08" izz="3.33718e-06" />
</inertial>
</link>
<joint name="trunk_1_trunk_1_13_high_leg_protection_left_fixing" type="fixed">
<origin xyz="-0.121675 -0.053727 -0.0035" rpy="1.87755e-18 5.37713e-17 2.61856e-13" />
<parent link="trunk_1" />
<child link="trunk_1_13_high_leg_protection_left" />
<axis xyz="0 0 0"/>
</joint>

<link name="trunk_1_14_torso_top_plate_nuc">
<collision>
<origin xyz="0 -0.012 0.0015" rpy="0 -0 0" />
<geometry>
<box size="0.13 0.08 0.003" />
</geometry>
<material name="trunk_1_14_torso_top_plate_nuc_material">
<color rgba="0.301961 0.301961 0.301961 1.0"/>
</material>
</collision>
<visual>
<origin xyz="0 -0.012 0.0015" rpy="0 -0 0" />
<geometry>
<box size="0.13 0.08 0.003" />
</geometry>
<material name="trunk_1_14_torso_top_plate_nuc_material">
<color rgba="0.301961 0.301961 0.301961 1.0"/>
</material>
</visual>
<inertial>
<origin xyz="1.26599e-05 -0.0116052 0.00149732" rpy="0 0 0"/>
<mass value="0.0826547"/>
<inertia ixx="5.06885e-05" ixy="3.49442e-08"  ixz="-2.80418e-12" iyy="0.000127749" iyz="2.34131e-09" izz="0.000178314" />
</inertial>
</link>
<joint name="trunk_1_trunk_1_14_torso_top_plate_nuc_fixing" type="fixed">
<origin xyz="9.63118e-15 -0.0065 0.1369" rpy="3.14159 -5.37713e-17 -3.14159" />
<parent link="trunk_1" />
<child link="trunk_1_14_torso_top_plate_nuc" />
<axis xyz="0 0 0"/>
</joint>

<link name="trunk_1_15_torso_middle_plate_nuc">
<collision>
<origin xyz="0 0.015 0.0015" rpy="0 -0 0" />
<geometry>
<box size="0.13 0.08 0.003" />
</geometry>
<material name="trunk_1_15_torso_middle_plate_nuc_material">
<color rgba="0.301961 0.301961 0.301961 1.0"/>
</material>
</collision>
<visual>
<origin xyz="0 0.015 0.0015" rpy="0 -0 0" />
<geometry>
<box size="0.13 0.08 0.003" />
</geometry>
<material name="trunk_1_15_torso_middle_plate_nuc_material">
<color rgba="0.301961 0.301961 0.301961 1.0"/>
</material>
</visual>
<inertial>
<origin xyz="1.15517e-17 0.00139372 0.00149794" rpy="0 0 0"/>
<mass value="0.107742"/>
<inertia ixx="0.000114709" ixy="0"  ixz="0" iyy="0.000172222" iyz="-1.09084e-09" izz="0.000286769" />
</inertial>
</link>
<joint name="trunk_1_trunk_1_15_torso_middle_plate_nuc_fixing" type="fixed">
<origin xyz="9.45251e-15 -0.004 0.0453999" rpy="1.87755e-18 5.37713e-17 8.67223e-14" />
<parent link="trunk_1" />
<child link="trunk_1_15_torso_middle_plate_nuc" />
<axis xyz="0 0 0"/>
</joint>

<link name="trunk_1_16_pillar_tube">
<collision>
<origin xyz="0 0 0.043" rpy="0 -0 0" />
<geometry>
<cylinder length="0.086" radius="0.004" />
</geometry>
<material name="trunk_1_16_pillar_tube_material">
<color rgba="0.501961 0.486275 0.439216 1.0"/>
</material>
</collision>
<visual>
<origin xyz="0 0 0.043" rpy="0 -0 0" />
<geometry>
<cylinder length="0.086" radius="0.004" />
</geometry>
<material name="trunk_1_16_pillar_tube_material">
<color rgba="0.501961 0.486275 0.439216 1.0"/>
</material>
</visual>
<inertial>
<origin xyz="1.97891e-19 3.23657e-19 0.043" rpy="0 0 0"/>
<mass value="0.0148462"/>
<inertia ixx="9.24301e-06" ixy="0"  ixz="0" iyy="9.24301e-06" iyz="0" izz="1.85578e-07" />
</inertial>
</link>
<joint name="trunk_1_trunk_1_16_pillar_tube_fixing" type="fixed">
<origin xyz="-0.0625 0.0385 0.0478999" rpy="1.87755e-18 5.37713e-17 8.68376e-14" />
<parent link="trunk_1" />
<child link="trunk_1_16_pillar_tube" />
<axis xyz="0 0 0"/>
</joint>

<link name="trunk_1_17_nuc">
<collision>
<origin xyz="0 0 0.016" rpy="0 -0 0" />
<geometry>
<box size="0.11 0.11 0.033" />
</geometry>
<material name="trunk_1_17_nuc_material">
<color rgba="0.301961 0.290196 0.262745 1.0"/>
</material>
</collision>
<visual>
<origin xyz="0 0 0.016" rpy="0 -0 0" />
<geometry>
<box size="0.11 0.11 0.033" />
</geometry>
<material name="trunk_1_17_nuc_material">
<color rgba="0.301961 0.290196 0.262745 1.0"/>
</material>
</visual>
<inertial>
<origin xyz="2.44557e-05 -0.000410789 0.0164318" rpy="0 0 0"/>
<mass value="0.444931"/>
<inertia ixx="0.000501859" ixy="5.68914e-07"  ixz="1.67402e-08" iyy="0.000526895" iyz="-3.85289e-07" izz="0.000948096" />
</inertial>
</link>
<joint name="trunk_1_trunk_1_17_nuc_fixing" type="fixed">
<origin xyz="9.20097e-15 0.0205 0.10615" rpy="1.5708 1.32925e-16 -3.14159" />
<parent link="trunk_1" />
<child link="trunk_1_17_nuc" />
<axis xyz="0 0 0"/>
</joint>

<link name="trunk_1_18_backmarker">
<inertial>
<origin xyz="2.4832e-18 -0.0015 0.045" rpy="0 0 0"/>
<mass value="0.00667279"/>
<inertia ixx="3.72487e-06" ixy="0"  ixz="0" iyy="1.21031e-05" iyz="0" izz="8.37932e-06" />
</inertial>
</link>
<joint name="trunk_1_trunk_1_18_backmarker_fixing" type="fixed">
<origin xyz="0.0005 0.0585 0" rpy="-1.87755e-18 -5.37713e-17 -3.14159" />
<parent link="trunk_1" />
<child link="trunk_1_18_backmarker" />
<axis xyz="0 0 0"/>
</joint>

<link name="trunk_1_19_nuc_fix">
<collision>
<origin xyz="-0.007 0 0.0015" rpy="0 -0 0" />
<geometry>
<box size="0.01 0.135 0.003" />
</geometry>
<material name="trunk_1_19_nuc_fix_material">
<color rgba="0.301961 0.301961 0.301961 1.0"/>
</material>
</collision>
<visual>
<origin xyz="-0.007 0 0.0015" rpy="0 -0 0" />
<geometry>
<box size="0.01 0.135 0.003" />
</geometry>
<material name="trunk_1_19_nuc_fix_material">
<color rgba="0.301961 0.301961 0.301961 1.0"/>
</material>
</visual>
<inertial>
<origin xyz="-0.00474564 -1.59496e-19 0.0015" rpy="0 0 0"/>
<mass value="0.0176383"/>
<inertia ixx="3.15829e-05" ixy="0"  ixz="0" iyy="8.54293e-07" iyz="0" izz="3.24108e-05" />
</inertial>
</link>
<joint name="trunk_1_trunk_1_19_nuc_fix_fixing" type="fixed">
<origin xyz="4.3715e-15 0.053 0.1399" rpy="3.14159 1.87755e-18 -1.5708" />
<parent link="trunk_1" />
<child link="trunk_1_19_nuc_fix" />
<axis xyz="0 0 0"/>
</joint>

<link name="trunk_1_20_torsoprotect">
<inertial>
<origin xyz="-0.00155672 0.0387748 0.0457555" rpy="0 0 0"/>
<mass value="0.0315682"/>
<inertia ixx="7.3819e-05" ixy="4.0421e-07"  ixz="-1.65884e-06" iyy="0.000130143" iyz="-1.96161e-07" izz="0.000162049" />
</inertial>
</link>
<joint name="trunk_1_trunk_1_20_torsoprotect_fixing" type="fixed">
<origin xyz="1.36904e-14 -0.0635 0.0438999" rpy="1.87755e-18 5.37713e-17 8.68683e-14" />
<parent link="trunk_1" />
<child link="trunk_1_20_torsoprotect" />
<axis xyz="0 0 0"/>
</joint>

<link name="trunk_1_21_piano_wire_back_fixation">
<inertial>
<origin xyz="0.00664685 0.00830315 0.00277132" rpy="0 0 0"/>
<mass value="0.00242365"/>
<inertia ixx="5.11774e-08" ixy="-1.06263e-08"  ixz="-4.74489e-10" iyy="5.11774e-08" iyz="4.74489e-10" izz="8.85098e-08" />
</inertial>
</link>
<joint name="trunk_1_trunk_1_21_piano_wire_back_fixation_fixing" type="fixed">
<origin xyz="-0.052 0.0669 0.1459" rpy="3.14159 1.87755e-18 -1.5708" />
<parent link="trunk_1" />
<child link="trunk_1_21_piano_wire_back_fixation" />
<axis xyz="0 0 0"/>
</joint>

<link name="trunk_1_22_torsomarker">
<inertial>
<origin xyz="6.57501e-19 -0.0015 0.045" rpy="0 0 0"/>
<mass value="0.00667279"/>
<inertia ixx="3.72487e-06" ixy="0"  ixz="0" iyy="1.21031e-05" iyz="0" izz="8.37932e-06" />
</inertial>
</link>
<joint name="trunk_1_trunk_1_22_torsomarker_fixing" type="fixed">
<origin xyz="1.36904e-14 -0.0635 0.0438999" rpy="1.87755e-18 5.37713e-17 8.68683e-14" />
<parent link="trunk_1" />
<child link="trunk_1_22_torsomarker" />
<axis xyz="0 0 0"/>
</joint>

<link name="trunk_1_23_mx64">
<collision>
<origin xyz="0 -0.015 0" rpy="0 -0 0" />
<geometry>
<box size="0.029 0.05 0.04" />
</geometry>
<material name="trunk_1_23_mx64_material">
<color rgba="0.211765 0.211765 0.211765 1.0"/>
</material>
</collision>
<visual>
<origin xyz="0 -0.015 0" rpy="0 -0 0" />
<geometry>
<box size="0.029 0.05 0.04" />
</geometry>
<material name="trunk_1_23_mx64_material">
<color rgba="0.211765 0.211765 0.211765 1.0"/>
</material>
</visual>
<inertial>
<origin xyz="0 0 0.00254" rpy="0 0 0"/>
<mass value="0.158"/>
<inertia ixx="7.869e-05" ixy="-8.4e-07"  ixz="4.9e-07" iyy="4.097e-05" iyz="-9.14e-06" izz="6.136e-05" />
</inertial>
</link>
<joint name="trunk_1_trunk_1_23_mx64_fixing" type="fixed">
<origin xyz="2.22422e-14 -0.0365 0.1623" rpy="1.12114e-14 -2.33618e-15 -3.14159" />
<parent link="trunk_1" />
<child link="trunk_1_23_mx64" />
<axis xyz="0 0 0"/>
</joint>

<link name="trunk_1_24_pillar_tube">
<collision>
<origin xyz="0 0 0.043" rpy="0 -0 0" />
<geometry>
<cylinder length="0.086" radius="0.004" />
</geometry>
<material name="trunk_1_24_pillar_tube_material">
<color rgba="0.501961 0.486275 0.439216 1.0"/>
</material>
</collision>
<visual>
<origin xyz="0 0 0.043" rpy="0 -0 0" />
<geometry>
<cylinder length="0.086" radius="0.004" />
</geometry>
<material name="trunk_1_24_pillar_tube_material">
<color rgba="0.501961 0.486275 0.439216 1.0"/>
</material>
</visual>
<inertial>
<origin xyz="1.97891e-19 3.23657e-19 0.043" rpy="0 0 0"/>
<mass value="0.0148462"/>
<inertia ixx="9.24301e-06" ixy="0"  ixz="0" iyy="9.24301e-06" iyz="0" izz="1.85578e-07" />
</inertial>
</link>
<joint name="trunk_1_trunk_1_24_pillar_tube_fixing" type="fixed">
<origin xyz="0.031 -0.0535 0.0483999" rpy="1.87755e-18 5.37713e-17 8.68376e-14" />
<parent link="trunk_1" />
<child link="trunk_1_24_pillar_tube" />
<axis xyz="0 0 0"/>
</joint>

<link name="trunk">
<inertial>
<origin xyz="0 0 0" rpy="0 0 0" />
<mass value="1e-9" />
<inertia ixx="0" ixy="0" ixz="0" iyy="0" iyz="0" izz="0" />
</inertial>
</link>
<joint name="trunk_frame" type="fixed">
<origin xyz="5.86824e-18 -0.010627 -0.0435" rpy="-1.09282e-16 1.57553e-17 -1.5708" />
<parent link="trunk_1" />
<child link="trunk" />
<axis xyz="0 0 0"/>
</joint>

<link name="head_base">
<inertial>
<origin xyz="0 0 0" rpy="0 0 0" />
<mass value="1e-9" />
<inertia ixx="0" ixy="0" ixz="0" iyy="0" iyz="0" izz="0" />
</inertial>
</link>
<joint name="head_base_frame" type="fixed">
<origin xyz="2.2253e-14 -0.0365 0.1858" rpy="-2.60157e-17 1.57553e-17 -1.5708" />
<parent link="trunk_1" />
<child link="head_base" />
<axis xyz="0 0 0"/>
</joint>

<link name="u_block_1">
<inertial>
<origin xyz="0 0 0" rpy="0 0 0" />
<mass value="1e-9" />
<inertia ixx="0" ixy="0" ixz="0" iyy="0" iyz="0" izz="0" />
</inertial>
</link>
<link name="u_block_1_0_u_base_motors_blocs">
<collision>
<origin xyz="0.026 0.015 0.003" rpy="0 -0 0" />
<geometry>
<box size="0.05 0.03 0.006" />
</geometry>
<material name="u_block_1_0_u_base_motors_blocs_material">
<color rgba="0.301961 0.301961 0.301961 1.0"/>
</material>
</collision>
<visual>
<origin xyz="0.026 0.015 0.003" rpy="0 -0 0" />
<geometry>
<box size="0.05 0.03 0.006" />
</geometry>
<material name="u_block_1_0_u_base_motors_blocs_material">
<color rgba="0.301961 0.301961 0.301961 1.0"/>
</material>
</visual>
<inertial>
<origin xyz="0.0258184 0.015 0.00240855" rpy="0 0 0"/>
<mass value="0.0177728"/>
<inertia ixx="1.53307e-06" ixy="0"  ixz="-2.55301e-09" iyy="4.59364e-06" iyz="0" izz="6.04516e-06" />
</inertial>
</link>
<joint name="u_block_1_u_block_1_0_u_base_motors_blocs_fixing" type="fixed">
<origin xyz="-0.03094 -0.015 0" rpy="6.68901e-45 2.70936e-35 -1.04225e-34" />
<parent link="u_block_1" />
<child link="u_block_1_0_u_base_motors_blocs" />
<axis xyz="0 0 0"/>
</joint>

<link name="u_block_1_1_u_side_small">
<collision>
<origin xyz="0.015 0.023 0.0015" rpy="0 -0 0" />
<geometry>
<box size="0.025 0.044 0.003" />
</geometry>
<material name="u_block_1_1_u_side_small_material">
<color rgba="0.301961 0.301961 0.301961 1.0"/>
</material>
</collision>
<visual>
<origin xyz="0.015 0.023 0.0015" rpy="0 -0 0" />
<geometry>
<box size="0.025 0.044 0.003" />
</geometry>
<material name="u_block_1_1_u_side_small_material">
<color rgba="0.301961 0.301961 0.301961 1.0"/>
</material>
</visual>
<inertial>
<origin xyz="0.015 0.0221162 0.00145795" rpy="0 0 0"/>
<mass value="0.00960981"/>
<inertia ixx="1.4711e-06" ixy="1.8235e-13"  ixz="-1.13892e-14" iyy="7.29209e-07" iyz="-7.82613e-09" izz="2.1862e-06" />
</inertial>
</link>
<joint name="u_block_1_u_block_1_1_u_side_small_fixing" type="fixed">
<origin xyz="-0.03294 -0.015 -9.1073e-18" rpy="1.5708 -9.35682e-17 1.5708" />
<parent link="u_block_1" />
<child link="u_block_1_1_u_side_small" />
<axis xyz="0 0 0"/>
</joint>

<link name="u_block_1_2_u_side_small_with_trace">
<collision>
<origin xyz="0.015 0.023 0.0015" rpy="0 -0 0" />
<geometry>
<box size="0.027 0.042 0.003" />
</geometry>
<material name="u_block_1_2_u_side_small_with_trace_material">
<color rgba="0.301961 0.301961 0.301961 1.0"/>
</material>
</collision>
<visual>
<origin xyz="0.015 0.023 0.0015" rpy="0 -0 0" />
<geometry>
<box size="0.027 0.042 0.003" />
</geometry>
<material name="u_block_1_2_u_side_small_with_trace_material">
<color rgba="0.301961 0.301961 0.301961 1.0"/>
</material>
</visual>
<inertial>
<origin xyz="0.015 0.0200591 0.00125723" rpy="0 0 0"/>
<mass value="0.00805776"/>
<inertia ixx="1.17632e-06" ixy="1.41838e-13"  ixz="7.6877e-14" iyy="6.21461e-07" iyz="1.27729e-08" izz="1.78795e-06" />
</inertial>
</link>
<joint name="u_block_1_u_block_1_2_u_side_small_with_trace_fixing" type="fixed">
<origin xyz="0.0234 0.015 -6.93889e-18" rpy="1.5708 -3.9526e-17 -1.5708" />
<parent link="u_block_1" />
<child link="u_block_1_2_u_side_small_with_trace" />
<axis xyz="0 0 0"/>
</joint>

<link name="mx106_block_mir_1">
<inertial>
<origin xyz="0 0 0" rpy="0 0 0" />
<mass value="1e-9" />
<inertia ixx="0" ixy="0" ixz="0" iyy="0" iyz="0" izz="0" />
</inertial>
</link>
<link name="mx106_block_mir_1_0_mx106">
<collision>
<origin xyz="0 -0.015 0" rpy="0 -0 0" />
<geometry>
<box size="0.03 0.055 0.04" />
</geometry>
<material name="mx106_block_mir_1_0_mx106_material">
<color rgba="0.301961 0.301961 0.301961 1.0"/>
</material>
</collision>
<visual>
<origin xyz="0 -0.015 0" rpy="0 -0 0" />
<geometry>
<box size="0.03 0.055 0.04" />
</geometry>
<material name="mx106_block_mir_1_0_mx106_material">
<color rgba="0.301961 0.301961 0.301961 1.0"/>
</material>
</visual>
<inertial>
<origin xyz="0 0 0.00254" rpy="0 0 0"/>
<mass value="0.158"/>
<inertia ixx="7.869e-05" ixy="-8.4e-07"  ixz="4.9e-07" iyy="4.097e-05" iyz="-9.14e-06" izz="6.136e-05" />
</inertial>
</link>
<joint name="mx106_block_mir_1_mx106_block_mir_1_0_mx106_fixing" type="fixed">
<origin xyz="-2.158e-14 -2.87964e-15 0.0234" rpy="2.89425e-13 -1.5708 0" />
<parent link="mx106_block_mir_1" />
<child link="mx106_block_mir_1_0_mx106" />
<axis xyz="0 0 0"/>
</joint>

<link name="mx106_block_mir_1_1_mx106">
<collision>
<origin xyz="0 -0.015 0" rpy="0 -0 0" />
<geometry>
<box size="0.03 0.055 0.04" />
</geometry>
<material name="mx106_block_mir_1_1_mx106_material">
<color rgba="0.301961 0.301961 0.301961 1.0"/>
</material>
</collision>
<visual>
<origin xyz="0 -0.015 0" rpy="0 -0 0" />
<geometry>
<box size="0.03 0.055 0.04" />
</geometry>
<material name="mx106_block_mir_1_1_mx106_material">
<color rgba="0.301961 0.301961 0.301961 1.0"/>
</material>
</visual>
<inertial>
<origin xyz="0 0 0.00254" rpy="0 0 0"/>
<mass value="0.158"/>
<inertia ixx="7.869e-05" ixy="-8.4e-07"  ixz="4.9e-07" iyy="4.097e-05" iyz="-9.14e-06" izz="6.136e-05" />
</inertial>
</link>
<joint name="mx106_block_mir_1_mx106_block_mir_1_1_mx106_fixing" type="fixed">
<origin xyz="0 -6.93889e-18 -0.026" rpy="-1.76736e-34 3.87639e-32 -1.38051e-29" />
<parent link="mx106_block_mir_1" />
<child link="mx106_block_mir_1_1_mx106" />
<axis xyz="0 0 0"/>
</joint>

<link name="right_knee_1">
<inertial>
<origin xyz="0 0 0" rpy="0 0 0" />
<mass value="1e-9" />
<inertia ixx="0" ixy="0" ixz="0" iyy="0" iyz="0" izz="0" />
</inertial>
</link>
<link name="right_knee_1_0_u_side_femur_mir">
<collision>
<origin xyz="0 0.046 0.0445" rpy="0 -0 0" />
<geometry>
<box size="0.04 0.09 0.003" />
</geometry>
<material name="right_knee_1_0_u_side_femur_mir_material">
<color rgba="0.301961 0.301961 0.301961 1.0"/>
</material>
</collision>
<visual>
<origin xyz="0 0.046 0.0445" rpy="0 -0 0" />
<geometry>
<box size="0.04 0.09 0.003" />
</geometry>
<material name="right_knee_1_0_u_side_femur_mir_material">
<color rgba="0.301961 0.301961 0.301961 1.0"/>
</material>
</visual>
<inertial>
<origin xyz="4.77564e-07 0.0488035 0.0445144" rpy="0 0 0"/>
<mass value="0.0288138"/>
<inertia ixx="1.85941e-05" ixy="-4.56832e-10"  ixz="1.50205e-12" iyy="3.96313e-06" iyz="1.91568e-08" izz="2.25143e-05" />
</inertial>
</link>
<joint name="right_knee_1_right_knee_1_0_u_side_femur_mir_fixing" type="fixed">
<origin xyz="2.42861e-16 -0.0855 0.009" rpy="4.996e-16 -2.77556e-16 1.32533e-15" />
<parent link="right_knee_1" />
<child link="right_knee_1_0_u_side_femur_mir" />
<axis xyz="0 0 0"/>
</joint>

<link name="right_knee_1_1_mx106">
<collision>
<origin xyz="0 -0.015 0" rpy="0 -0 0" />
<geometry>
<box size="0.03 0.055 0.04" />
</geometry>
<material name="right_knee_1_1_mx106_material">
<color rgba="0.301961 0.301961 0.301961 1.0"/>
</material>
</collision>
<visual>
<origin xyz="0 -0.015 0" rpy="0 -0 0" />
<geometry>
<box size="0.03 0.055 0.04" />
</geometry>
<material name="right_knee_1_1_mx106_material">
<color rgba="0.301961 0.301961 0.301961 1.0"/>
</material>
</visual>
<inertial>
<origin xyz="0 0 0.00254" rpy="0 0 0"/>
<mass value="0.158"/>
<inertia ixx="7.869e-05" ixy="-8.4e-07"  ixz="4.9e-07" iyy="4.097e-05" iyz="-9.14e-06" izz="6.136e-05" />
</inertial>
</link>
<joint name="right_knee_1_right_knee_1_1_mx106_fixing" type="fixed">
<origin xyz="3.21479e-14 -0.14 0.026" rpy="-3.14159 -1.81887e-16 4.5397e-13" />
<parent link="right_knee_1" />
<child link="right_knee_1_1_mx106" />
<axis xyz="0 0 0"/>
</joint>

<link name="right_knee_1_2_u_side_femur">
<collision>
<origin xyz="0 0.046 0.0015" rpy="0 -0 0" />
<geometry>
<box size="0.04 0.09 0.003" />
</geometry>
<material name="right_knee_1_2_u_side_femur_material">
<color rgba="0.301961 0.301961 0.301961 1.0"/>
</material>
</collision>
<visual>
<origin xyz="0 0.046 0.0015" rpy="0 -0 0" />
<geometry>
<box size="0.04 0.09 0.003" />
</geometry>
<material name="right_knee_1_2_u_side_femur_material">
<color rgba="0.301961 0.301961 0.301961 1.0"/>
</material>
</visual>
<inertial>
<origin xyz="-4.77564e-07 0.0488035 0.00148556" rpy="0 0 0"/>
<mass value="0.0288138"/>
<inertia ixx="1.85941e-05" ixy="4.56832e-10"  ixz="1.50205e-12" iyy="3.96313e-06" iyz="-1.91568e-08" izz="2.25143e-05" />
</inertial>
</link>
<joint name="right_knee_1_right_knee_1_2_u_side_femur_fixing" type="fixed">
<origin xyz="0 -0.0855 -0.003" rpy="3.00051e-33 2.63221e-32 9.62319e-33" />
<parent link="right_knee_1" />
<child link="right_knee_1_2_u_side_femur" />
<axis xyz="0 0 0"/>
</joint>

<link name="right_knee_1_3_u_base_64">
<collision>
<origin xyz="0 0 0.003" rpy="0 -0 0" />
<geometry>
<box size="0.047 0.0275 0.006" />
</geometry>
<material name="right_knee_1_3_u_base_64_material">
<color rgba="0.301961 0.301961 0.301961 1.0"/>
</material>
</collision>
<visual>
<origin xyz="0 0 0.003" rpy="0 -0 0" />
<geometry>
<box size="0.047 0.0275 0.006" />
</geometry>
<material name="right_knee_1_3_u_base_64_material">
<color rgba="0.301961 0.301961 0.301961 1.0"/>
</material>
</visual>
<inertial>
<origin xyz="4.81338e-18 5.58165e-18 0.00242943" rpy="0 0 0"/>
<mass value="0.0187515"/>
<inertia ixx="1.62318e-06" ixy="0"  ixz="0" iyy="5.19793e-06" iyz="0" izz="6.73182e-06" />
</inertial>
</link>
<joint name="right_knee_1_right_knee_1_3_u_base_64_fixing" type="fixed">
<origin xyz="3.71231e-16 -0.0855 0.026" rpy="-1.5708 1.5708 0" />
<parent link="right_knee_1" />
<child link="right_knee_1_3_u_base_64" />
<axis xyz="0 0 0"/>
</joint>

<link name="tibia_1">
<inertial>
<origin xyz="0 0 0" rpy="0 0 0" />
<mass value="1e-9" />
<inertia ixx="0" ixy="0" ixz="0" iyy="0" iyz="0" izz="0" />
</inertial>
</link>
<link name="tibia_1_0_tibia_plate">
<collision>
<origin xyz="0 -0.067 0.0015" rpy="0 -0 0" />
<geometry>
<box size="0.03 0.165 0.003" />
</geometry>
<material name="tibia_1_0_tibia_plate_material">
<color rgba="0.301961 0.301961 0.301961 1.0"/>
</material>
</collision>
<visual>
<origin xyz="0 -0.067 0.0015" rpy="0 -0 0" />
<geometry>
<box size="0.03 0.165 0.003" />
</geometry>
<material name="tibia_1_0_tibia_plate_material">
<color rgba="0.301961 0.301961 0.301961 1.0"/>
</material>
</visual>
<inertial>
<origin xyz="-0.00342169 -0.0646068 0.00149999" rpy="0 0 0"/>
<mass value="0.0444219"/>
<inertia ixx="8.90296e-05" ixy="3.06359e-06"  ixz="-7.21428e-12" iyy="4.7687e-06" iyz="1.9033e-11" izz="9.37317e-05" />
</inertial>
</link>
<joint name="tibia_1_tibia_1_0_tibia_plate_fixing" type="fixed">
<origin xyz="0 0 0" rpy="0 -7.18604e-32 0" />
<parent link="tibia_1" />
<child link="tibia_1_0_tibia_plate" />
<axis xyz="0 0 0"/>
</joint>

<link name="tibia_1_1_tibia_plate">
<collision>
<origin xyz="0 -0.067 0.0015" rpy="0 -0 0" />
<geometry>
<box size="0.03 0.165 0.003" />
</geometry>
<material name="tibia_1_1_tibia_plate_material">
<color rgba="0.301961 0.301961 0.301961 1.0"/>
</material>
</collision>
<visual>
<origin xyz="0 -0.067 0.0015" rpy="0 -0 0" />
<geometry>
<box size="0.03 0.165 0.003" />
</geometry>
<material name="tibia_1_1_tibia_plate_material">
<color rgba="0.301961 0.301961 0.301961 1.0"/>
</material>
</visual>
<inertial>
<origin xyz="-0.00342169 -0.0646068 0.00149999" rpy="0 0 0"/>
<mass value="0.0444219"/>
<inertia ixx="8.90296e-05" ixy="3.06359e-06"  ixz="-7.21428e-12" iyy="4.7687e-06" iyz="1.9033e-11" izz="9.37317e-05" />
</inertial>
</link>
<joint name="tibia_1_tibia_1_1_tibia_plate_fixing" type="fixed">
<origin xyz="-1.21431e-17 1.11022e-16 -0.055" rpy="1.66533e-15 3.60822e-16 -1.11022e-16" />
<parent link="tibia_1" />
<child link="tibia_1_1_tibia_plate" />
<axis xyz="0 0 0"/>
</joint>

<link name="mx106_block_1">
<inertial>
<origin xyz="0 0 0" rpy="0 0 0" />
<mass value="1e-9" />
<inertia ixx="0" ixy="0" ixz="0" iyy="0" iyz="0" izz="0" />
</inertial>
</link>
<link name="mx106_block_1_0_mx106">
<collision>
<origin xyz="0 -0.015 0" rpy="0 -0 0" />
<geometry>
<box size="0.03 0.055 0.04" />
</geometry>
<material name="mx106_block_1_0_mx106_material">
<color rgba="0.301961 0.301961 0.301961 1.0"/>
</material>
</collision>
<visual>
<origin xyz="0 -0.015 0" rpy="0 -0 0" />
<geometry>
<box size="0.03 0.055 0.04" />
</geometry>
<material name="mx106_block_1_0_mx106_material">
<color rgba="0.301961 0.301961 0.301961 1.0"/>
</material>
</visual>
<inertial>
<origin xyz="0 0 0.00254" rpy="0 0 0"/>
<mass value="0.158"/>
<inertia ixx="7.869e-05" ixy="-8.4e-07"  ixz="4.9e-07" iyy="4.097e-05" iyz="-9.14e-06" izz="6.136e-05" />
</inertial>
</link>
<joint name="mx106_block_1_mx106_block_1_0_mx106_fixing" type="fixed">
<origin xyz="1.73472e-18 0 -0.026" rpy="3.75334e-32 1.7926e-31 -5.31975e-30" />
<parent link="mx106_block_1" />
<child link="mx106_block_1_0_mx106" />
<axis xyz="0 0 0"/>
</joint>

<link name="mx106_block_1_1_mx106">
<collision>
<origin xyz="0 -0.015 0" rpy="0 -0 0" />
<geometry>
<box size="0.03 0.055 0.04" />
</geometry>
<material name="mx106_block_1_1_mx106_material">
<color rgba="0.301961 0.301961 0.301961 1.0"/>
</material>
</collision>
<visual>
<origin xyz="0 -0.015 0" rpy="0 -0 0" />
<geometry>
<box size="0.03 0.055 0.04" />
</geometry>
<material name="mx106_block_1_1_mx106_material">
<color rgba="0.301961 0.301961 0.301961 1.0"/>
</material>
</visual>
<inertial>
<origin xyz="0 0 0.00254" rpy="0 0 0"/>
<mass value="0.158"/>
<inertia ixx="7.869e-05" ixy="-8.4e-07"  ixz="4.9e-07" iyy="4.097e-05" iyz="-9.14e-06" izz="6.136e-05" />
</inertial>
</link>
<joint name="mx106_block_1_mx106_block_1_1_mx106_fixing" type="fixed">
<origin xyz="0.0494 -4.55191e-15 -0.026" rpy="7.80481e-16 -1.5708 0" />
<parent link="mx106_block_1" />
<child link="mx106_block_1_1_mx106" />
<axis xyz="0 0 0"/>
</joint>

<link name="right_foot_1">
<inertial>
<origin xyz="0 0 0" rpy="0 0 0" />
<mass value="1e-9" />
<inertia ixx="0" ixy="0" ixz="0" iyy="0" iyz="0" izz="0" />
</inertial>
</link>
<link name="right_foot_cleat_back_right">
<collision>
<origin xyz="0 0.01 0" rpy="1.5708 -0 0" />
<geometry>
<cylinder length="0.02" radius="0.008" />
</geometry>
<material name="right_foot_cleat_back_right_material">
<color rgba="0.301961 0.290196 0.262745 1.0"/>
</material>
</collision>
<visual>
<origin xyz="0 0.01 0" rpy="1.5708 -0 0" />
<geometry>
<cylinder length="0.02" radius="0.008" />
</geometry>
<material name="right_foot_cleat_back_right_material">
<color rgba="0.301961 0.290196 0.262745 1.0"/>
</material>
</visual>
<inertial>
<origin xyz="4.88654e-18 0.00894735 -1.23609e-35" rpy="0 0 0"/>
<mass value="0.00284785"/>
<inertia ixx="9.93965e-08" ixy="0"  ixz="0" iyy="8.64315e-08" iyz="0" izz="9.93965e-08" />
</inertial>
</link>
<joint name="right_foot_1_right_foot_cleat_back_right_fixing" type="fixed">
<origin xyz="-0.0435 -0.06 -0.03213" rpy="-3.14159 0.199727 3.14159" />
<parent link="right_foot_1" />
<child link="right_foot_cleat_back_right" />
<axis xyz="0 0 0"/>
</joint>

<link name="right_foot_cleat_front_right">
<collision>
<origin xyz="0 0.01 0" rpy="1.5708 -0 0" />
<geometry>
<cylinder length="0.02" radius="0.008" />
</geometry>
<material name="right_foot_cleat_front_right_material">
<color rgba="0.301961 0.290196 0.262745 1.0"/>
</material>
</collision>
<visual>
<origin xyz="0 0.01 0" rpy="1.5708 -0 0" />
<geometry>
<cylinder length="0.02" radius="0.008" />
</geometry>
<material name="right_foot_cleat_front_right_material">
<color rgba="0.301961 0.290196 0.262745 1.0"/>
</material>
</visual>
<inertial>
<origin xyz="4.88654e-18 0.00894735 -1.23609e-35" rpy="0 0 0"/>
<mass value="0.00284785"/>
<inertia ixx="9.93965e-08" ixy="0"  ixz="0" iyy="8.64315e-08" iyz="0" izz="9.93965e-08" />
</inertial>
</link>
<joint name="right_foot_1_right_foot_cleat_front_right_fixing" type="fixed">
<origin xyz="-0.0435 -0.06 0.10947" rpy="-3.14159 0.199727 3.14159" />
<parent link="right_foot_1" />
<child link="right_foot_cleat_front_right" />
<axis xyz="0 0 0"/>
</joint>

<link name="right_foot_1_2_u_side_small">
<collision>
<origin xyz="0.015 0.023 0.0015" rpy="0 -0 0" />
<geometry>
<box size="0.025 0.044 0.003" />
</geometry>
<material name="right_foot_1_2_u_side_small_material">
<color rgba="0.301961 0.301961 0.301961 1.0"/>
</material>
</collision>
<visual>
<origin xyz="0.015 0.023 0.0015" rpy="0 -0 0" />
<geometry>
<box size="0.025 0.044 0.003" />
</geometry>
<material name="right_foot_1_2_u_side_small_material">
<color rgba="0.301961 0.301961 0.301961 1.0"/>
</material>
</visual>
<inertial>
<origin xyz="0.015 0.0221162 0.00145795" rpy="0 0 0"/>
<mass value="0.00960981"/>
<inertia ixx="1.4711e-06" ixy="1.8235e-13"  ixz="-1.13892e-14" iyy="7.29209e-07" iyz="-7.82613e-09" izz="2.1862e-06" />
</inertial>
</link>
<joint name="right_foot_1_right_foot_1_2_u_side_small_fixing" type="fixed">
<origin xyz="0.015 -0.04 0.05634" rpy="-3.14159 -2.42855e-17 3.14159" />
<parent link="right_foot_1" />
<child link="right_foot_1_2_u_side_small" />
<axis xyz="0 0 0"/>
</joint>

<link name="right_foot_clear_front_left">
<collision>
<origin xyz="0 0.01 0" rpy="1.5708 -0 0" />
<geometry>
<cylinder length="0.02" radius="0.008" />
</geometry>
<material name="right_foot_clear_front_left_material">
<color rgba="0.301961 0.290196 0.262745 1.0"/>
</material>
</collision>
<visual>
<origin xyz="0 0.01 0" rpy="1.5708 -0 0" />
<geometry>
<cylinder length="0.02" radius="0.008" />
</geometry>
<material name="right_foot_clear_front_left_material">
<color rgba="0.301961 0.290196 0.262745 1.0"/>
</material>
</visual>
<inertial>
<origin xyz="4.88654e-18 0.00894735 -1.23609e-35" rpy="0 0 0"/>
<mass value="0.00284785"/>
<inertia ixx="9.93965e-08" ixy="0"  ixz="0" iyy="8.64315e-08" iyz="0" izz="9.93965e-08" />
</inertial>
</link>
<joint name="right_foot_1_right_foot_clear_front_left_fixing" type="fixed">
<origin xyz="0.0325 -0.06 0.10947" rpy="-9.21695e-16 0.555221 -2.37021e-15" />
<parent link="right_foot_1" />
<child link="right_foot_clear_front_left" />
<axis xyz="0 0 0"/>
</joint>

<link name="right_foot_1_4_foot_plate">
<collision>
<origin xyz="0 0 0.0015" rpy="0 -0 0" />
<geometry>
<box size="0.09 0.155 0.003" />
</geometry>
<material name="right_foot_1_4_foot_plate_material">
<color rgba="0.301961 0.301961 0.301961 1.0"/>
</material>
</collision>
<visual>
<origin xyz="0 0 0.0015" rpy="0 -0 0" />
<geometry>
<box size="0.09 0.155 0.003" />
</geometry>
<material name="right_foot_1_4_foot_plate_material">
<color rgba="0.301961 0.301961 0.301961 1.0"/>
</material>
</visual>
<inertial>
<origin xyz="6.4782e-18 0.00163454 0.0015" rpy="0 0 0"/>
<mass value="0.10146"/>
<inertia ixx="0.00020829" ixy="0"  ixz="0" iyy="7.17162e-05" iyz="0" izz="0.000279854" />
</inertial>
</link>
<joint name="right_foot_1_right_foot_1_4_foot_plate_fixing" type="fixed">
<origin xyz="-0.0055 -0.043 0.03867" rpy="1.5708 -2.34865e-17 3.14159" />
<parent link="right_foot_1" />
<child link="right_foot_1_4_foot_plate" />
<axis xyz="0 0 0"/>
</joint>

<link name="right_foot_1_5_u_side_small_with_trace">
<collision>
<origin xyz="0.015 0.023 0.0015" rpy="0 -0 0" />
<geometry>
<box size="0.027 0.042 0.003" />
</geometry>
<material name="right_foot_1_5_u_side_small_with_trace_material">
<color rgba="0.301961 0.301961 0.301961 1.0"/>
</material>
</collision>
<visual>
<origin xyz="0.015 0.023 0.0015" rpy="0 -0 0" />
<geometry>
<box size="0.027 0.042 0.003" />
</geometry>
<material name="right_foot_1_5_u_side_small_with_trace_material">
<color rgba="0.301961 0.301961 0.301961 1.0"/>
</material>
</visual>
<inertial>
<origin xyz="0.015 0.0200591 0.00125723" rpy="0 0 0"/>
<mass value="0.00805776"/>
<inertia ixx="1.17632e-06" ixy="1.41838e-13"  ixz="7.6877e-14" iyy="6.21461e-07" iyz="1.27729e-08" izz="1.78795e-06" />
</inertial>
</link>
<joint name="right_foot_1_right_foot_1_5_u_side_small_with_trace_fixing" type="fixed">
<origin xyz="-0.015 -0.04 1.73472e-18" rpy="-1.37633e-30 3.22292e-32 -3.37136e-31" />
<parent link="right_foot_1" />
<child link="right_foot_1_5_u_side_small_with_trace" />
<axis xyz="0 0 0"/>
</joint>

<link name="right_foot_cleat_back_left">
<collision>
<origin xyz="0 0.01 0" rpy="1.5708 -0 0" />
<geometry>
<cylinder length="0.02" radius="0.008" />
</geometry>
<material name="right_foot_cleat_back_left_material">
<color rgba="0.301961 0.290196 0.262745 1.0"/>
</material>
</collision>
<visual>
<origin xyz="0 0.01 0" rpy="1.5708 -0 0" />
<geometry>
<cylinder length="0.02" radius="0.008" />
</geometry>
<material name="right_foot_cleat_back_left_material">
<color rgba="0.301961 0.290196 0.262745 1.0"/>
</material>
</visual>
<inertial>
<origin xyz="4.88654e-18 0.00894735 -1.23609e-35" rpy="0 0 0"/>
<mass value="0.00284785"/>
<inertia ixx="9.93965e-08" ixy="0"  ixz="0" iyy="8.64315e-08" iyz="0" izz="9.93965e-08" />
</inertial>
</link>
<joint name="right_foot_1_right_foot_cleat_back_left_fixing" type="fixed">
<origin xyz="0.0325 -0.06 -0.03213" rpy="-1.27382e-15 -0.311457 -2.11626e-15" />
<parent link="right_foot_1" />
<child link="right_foot_cleat_back_left" />
<axis xyz="0 0 0"/>
</joint>

<link name="right_foot_1_7_foot_protection">
<collision>
<origin xyz="-0.019 -0.0275 0.0125" rpy="0 0.785398 0" />
<geometry>
<box size="0.01 0.09 0.01" />
</geometry>
<material name="right_foot_1_7_foot_protection_material">
<color rgba="0.301961 0.290196 0.262745 1.0"/>
</material>
</collision>
<visual>
<origin xyz="-0.019 -0.0275 0.0125" rpy="0 0.785398 0" />
<geometry>
<box size="0.01 0.09 0.01" />
</geometry>
<material name="right_foot_1_7_foot_protection_material">
<color rgba="0.301961 0.290196 0.262745 1.0"/>
</material>
</visual>
<inertial>
<origin xyz="-0.00751487 -0.0275 0.0127382" rpy="0 0 0"/>
<mass value="0.0434827"/>
<inertia ixx="1.82682e-05" ixy="0"  ixz="-1.2295e-06" iyy="9.28949e-06" iyz="0" izz="2.43902e-05" />
</inertial>
</link>
<joint name="right_foot_1_right_foot_1_7_foot_protection_fixing" type="fixed">
<origin xyz="-0.033 -0.04 0.10347" rpy="-1.5708 1.5708 0" />
<parent link="right_foot_1" />
<child link="right_foot_1_7_foot_protection" />
<axis xyz="0 0 0"/>
</joint>

<link name="right_foot_1_8_u_base_motors_blocs">
<collision>
<origin xyz="0.026 0.015 0.003" rpy="0 -0 0" />
<geometry>
<box size="0.05 0.03 0.006" />
</geometry>
<material name="right_foot_1_8_u_base_motors_blocs_material">
<color rgba="0.301961 0.301961 0.301961 1.0"/>
</material>
</collision>
<visual>
<origin xyz="0.026 0.015 0.003" rpy="0 -0 0" />
<geometry>
<box size="0.05 0.03 0.006" />
</geometry>
<material name="right_foot_1_8_u_base_motors_blocs_material">
<color rgba="0.301961 0.301961 0.301961 1.0"/>
</material>
</visual>
<inertial>
<origin xyz="0.0258184 0.015 0.00240855" rpy="0 0 0"/>
<mass value="0.0177728"/>
<inertia ixx="1.53307e-06" ixy="0"  ixz="-2.55301e-09" iyy="4.59364e-06" iyz="0" izz="6.04516e-06" />
</inertial>
</link>
<joint name="right_foot_1_right_foot_1_8_u_base_motors_blocs_fixing" type="fixed">
<origin xyz="0.015 -0.04 0.05434" rpy="-1.5708 1.5708 0" />
<parent link="right_foot_1" />
<child link="right_foot_1_8_u_base_motors_blocs" />
<axis xyz="0 0 0"/>
</joint>

<link name="right_foot">
<inertial>
<origin xyz="0 0 0" rpy="0 0 0" />
<mass value="1e-9" />
<inertia ixx="0" ixy="0" ixz="0" iyy="0" iyz="0" izz="0" />
</inertial>
</link>
<joint name="right_foot_frame" type="fixed">
<origin xyz="-6.245e-17 -0.06 0.02317" rpy="-1.5708 -1.5708 0" />
<parent link="right_foot_1" />
<child link="right_foot" />
<axis xyz="0 0 0"/>
</joint>

<joint name="right_ankle_roll" type="revolute">
<origin xyz="0.0234 -4.55191e-15 -0.026" rpy="3.14159 1.5708 0" />
<parent link="mx106_block_1" />
<child link="right_foot_1" />
<axis xyz="-0 -0 1"/>
<limit effort="10" velocity="6" />
<joint_properties friction="0.0"/>
</joint>

<joint name="right_ankle_pitch" type="revolute">
<origin xyz="1.38778e-17 -0.14 1.38778e-17" rpy="-1.83187e-15 -2.77556e-16 3.14159" />
<parent link="tibia_1" />
<child link="mx106_block_1" />
<axis xyz="-0 -0 -1"/>
<limit effort="10" velocity="6" />
<joint_properties friction="0.0"/>
</joint>

<joint name="right_knee" type="revolute">
<origin xyz="3.21479e-14 -0.14 3.747e-16" rpy="3.14159 -3.36029e-16 -3.14159" />
<parent link="right_knee_1" />
<child link="tibia_1" />
<axis xyz="0 0 -1"/>
<limit effort="10" velocity="6" />
<joint_properties friction="0.0"/>
</joint>

<joint name="right_hip_pitch" type="revolute">
<origin xyz="-0.026 -1.03875e-14 0.0234" rpy="-2.8919e-13 1.5708 0" />
<parent link="mx106_block_mir_1" />
<child link="right_knee_1" />
<axis xyz="0 0 1"/>
<limit effort="10" velocity="6" />
<joint_properties friction="0.0"/>
</joint>

<joint name="right_hip_roll" type="revolute">
<origin xyz="0.0234 -4.16334e-17 0.04" rpy="-1.5708 -2.89657e-13 1.5708" />
<parent link="u_block_1" />
<child link="mx106_block_mir_1" />
<axis xyz="0 0 1"/>
<limit effort="10" velocity="6" />
<joint_properties friction="0.0"/>
</joint>

<joint name="right_hip_yaw" type="revolute">
<origin xyz="-0.046375 -0.010627 -0.0035" rpy="3.14159 -1.87755e-18 1.5708" />
<parent link="trunk_1" />
<child link="u_block_1" />
<axis xyz="0 0 -1"/>
<limit effort="10" velocity="6" />
<joint_properties friction="0.0"/>
</joint>

<link name="u_block_2">
<inertial>
<origin xyz="0 0 0" rpy="0 0 0" />
<mass value="1e-9" />
<inertia ixx="0" ixy="0" ixz="0" iyy="0" iyz="0" izz="0" />
</inertial>
</link>
<link name="u_block_2_0_u_base_motors_blocs">
<collision>
<origin xyz="0.026 0.015 0.003" rpy="0 -0 0" />
<geometry>
<box size="0.05 0.03 0.006" />
</geometry>
<material name="u_block_2_0_u_base_motors_blocs_material">
<color rgba="0.301961 0.301961 0.301961 1.0"/>
</material>
</collision>
<visual>
<origin xyz="0.026 0.015 0.003" rpy="0 -0 0" />
<geometry>
<box size="0.05 0.03 0.006" />
</geometry>
<material name="u_block_2_0_u_base_motors_blocs_material">
<color rgba="0.301961 0.301961 0.301961 1.0"/>
</material>
</visual>
<inertial>
<origin xyz="0.0258184 0.015 0.00240855" rpy="0 0 0"/>
<mass value="0.0177728"/>
<inertia ixx="1.53307e-06" ixy="0"  ixz="-2.55301e-09" iyy="4.59364e-06" iyz="0" izz="6.04516e-06" />
</inertial>
</link>
<joint name="u_block_2_u_block_2_0_u_base_motors_blocs_fixing" type="fixed">
<origin xyz="-0.03094 -0.015 4.33681e-19" rpy="2.10889e-32 2.29196e-32 1.36063e-31" />
<parent link="u_block_2" />
<child link="u_block_2_0_u_base_motors_blocs" />
<axis xyz="0 0 0"/>
</joint>

<link name="u_block_2_1_u_side_small_with_trace">
<collision>
<origin xyz="0.015 0.023 0.0015" rpy="0 -0 0" />
<geometry>
<box size="0.027 0.042 0.003" />
</geometry>
<material name="u_block_2_1_u_side_small_with_trace_material">
<color rgba="0.301961 0.301961 0.301961 1.0"/>
</material>
</collision>
<visual>
<origin xyz="0.015 0.023 0.0015" rpy="0 -0 0" />
<geometry>
<box size="0.027 0.042 0.003" />
</geometry>
<material name="u_block_2_1_u_side_small_with_trace_material">
<color rgba="0.301961 0.301961 0.301961 1.0"/>
</material>
</visual>
<inertial>
<origin xyz="0.015 0.0200591 0.00125723" rpy="0 0 0"/>
<mass value="0.00805776"/>
<inertia ixx="1.17632e-06" ixy="1.41838e-13"  ixz="7.6877e-14" iyy="6.21461e-07" iyz="1.27729e-08" izz="1.78795e-06" />
</inertial>
</link>
<joint name="u_block_2_u_block_2_1_u_side_small_with_trace_fixing" type="fixed">
<origin xyz="0.0234 0.015 1.12757e-17" rpy="1.5708 -3.11126e-16 -1.5708" />
<parent link="u_block_2" />
<child link="u_block_2_1_u_side_small_with_trace" />
<axis xyz="0 0 0"/>
</joint>

<link name="u_block_2_2_u_side_small">
<collision>
<origin xyz="0.015 0.023 0.0015" rpy="0 -0 0" />
<geometry>
<box size="0.025 0.044 0.003" />
</geometry>
<material name="u_block_2_2_u_side_small_material">
<color rgba="0.301961 0.301961 0.301961 1.0"/>
</material>
</collision>
<visual>
<origin xyz="0.015 0.023 0.0015" rpy="0 -0 0" />
<geometry>
<box size="0.025 0.044 0.003" />
</geometry>
<material name="u_block_2_2_u_side_small_material">
<color rgba="0.301961 0.301961 0.301961 1.0"/>
</material>
</visual>
<inertial>
<origin xyz="0.015 0.0221162 0.00145795" rpy="0 0 0"/>
<mass value="0.00960981"/>
<inertia ixx="1.4711e-06" ixy="1.8235e-13"  ixz="-1.13892e-14" iyy="7.29209e-07" iyz="-7.82613e-09" izz="2.1862e-06" />
</inertial>
</link>
<joint name="u_block_2_u_block_2_2_u_side_small_fixing" type="fixed">
<origin xyz="-0.03294 -0.015 1.30104e-18" rpy="1.5708 2.61174e-16 1.5708" />
<parent link="u_block_2" />
<child link="u_block_2_2_u_side_small" />
<axis xyz="0 0 0"/>
</joint>

<link name="mx106_block_2">
<inertial>
<origin xyz="0 0 0" rpy="0 0 0" />
<mass value="1e-9" />
<inertia ixx="0" ixy="0" ixz="0" iyy="0" iyz="0" izz="0" />
</inertial>
</link>
<link name="mx106_block_2_0_mx106">
<collision>
<origin xyz="0 -0.015 0" rpy="0 -0 0" />
<geometry>
<box size="0.03 0.055 0.04" />
</geometry>
<material name="mx106_block_2_0_mx106_material">
<color rgba="0.301961 0.301961 0.301961 1.0"/>
</material>
</collision>
<visual>
<origin xyz="0 -0.015 0" rpy="0 -0 0" />
<geometry>
<box size="0.03 0.055 0.04" />
</geometry>
<material name="mx106_block_2_0_mx106_material">
<color rgba="0.301961 0.301961 0.301961 1.0"/>
</material>
</visual>
<inertial>
<origin xyz="0 0 0.00254" rpy="0 0 0"/>
<mass value="0.158"/>
<inertia ixx="7.869e-05" ixy="-8.4e-07"  ixz="4.9e-07" iyy="4.097e-05" iyz="-9.14e-06" izz="6.136e-05" />
</inertial>
</link>
<joint name="mx106_block_2_mx106_block_2_0_mx106_fixing" type="fixed">
<origin xyz="0 -6.93889e-18 -0.026" rpy="3.59352e-33 -6.66899e-31 -2.33147e-29" />
<parent link="mx106_block_2" />
<child link="mx106_block_2_0_mx106" />
<axis xyz="0 0 0"/>
</joint>

<link name="mx106_block_2_1_mx106">
<collision>
<origin xyz="0 -0.015 0" rpy="0 -0 0" />
<geometry>
<box size="0.03 0.055 0.04" />
</geometry>
<material name="mx106_block_2_1_mx106_material">
<color rgba="0.301961 0.301961 0.301961 1.0"/>
</material>
</collision>
<visual>
<origin xyz="0 -0.015 0" rpy="0 -0 0" />
<geometry>
<box size="0.03 0.055 0.04" />
</geometry>
<material name="mx106_block_2_1_mx106_material">
<color rgba="0.301961 0.301961 0.301961 1.0"/>
</material>
</visual>
<inertial>
<origin xyz="0 0 0.00254" rpy="0 0 0"/>
<mass value="0.158"/>
<inertia ixx="7.869e-05" ixy="-8.4e-07"  ixz="4.9e-07" iyy="4.097e-05" iyz="-9.14e-06" izz="6.136e-05" />
</inertial>
</link>
<joint name="mx106_block_2_mx106_block_2_1_mx106_fixing" type="fixed">
<origin xyz="-2.16008e-14 4.96825e-15 0.0234" rpy="-2.88049e-13 1.5708 0" />
<parent link="mx106_block_2" />
<child link="mx106_block_2_1_mx106" />
<axis xyz="0 0 0"/>
</joint>

<link name="left_knee_1">
<inertial>
<origin xyz="0 0 0" rpy="0 0 0" />
<mass value="1e-9" />
<inertia ixx="0" ixy="0" ixz="0" iyy="0" iyz="0" izz="0" />
</inertial>
</link>
<link name="left_knee_1_0_u_base_64">
<collision>
<origin xyz="0 0 0.003" rpy="0 -0 0" />
<geometry>
<box size="0.047 0.0275 0.006" />
</geometry>
<material name="left_knee_1_0_u_base_64_material">
<color rgba="0.301961 0.301961 0.301961 1.0"/>
</material>
</collision>
<visual>
<origin xyz="0 0 0.003" rpy="0 -0 0" />
<geometry>
<box size="0.047 0.0275 0.006" />
</geometry>
<material name="left_knee_1_0_u_base_64_material">
<color rgba="0.301961 0.301961 0.301961 1.0"/>
</material>
</visual>
<inertial>
<origin xyz="4.81338e-18 5.58165e-18 0.00242943" rpy="0 0 0"/>
<mass value="0.0187515"/>
<inertia ixx="1.62318e-06" ixy="0"  ixz="0" iyy="5.19793e-06" iyz="0" izz="6.73182e-06" />
</inertial>
</link>
<joint name="left_knee_1_left_knee_1_0_u_base_64_fixing" type="fixed">
<origin xyz="6.07153e-17 -0.0855 0.026" rpy="-1.5708 1.5708 0" />
<parent link="left_knee_1" />
<child link="left_knee_1_0_u_base_64" />
<axis xyz="0 0 0"/>
</joint>

<link name="left_knee_1_1_u_side_femur">
<collision>
<origin xyz="0 0.046 0.0015" rpy="0 -0 0" />
<geometry>
<box size="0.04 0.09 0.003" />
</geometry>
<material name="left_knee_1_1_u_side_femur_material">
<color rgba="0.301961 0.301961 0.301961 1.0"/>
</material>
</collision>
<visual>
<origin xyz="0 0.046 0.0015" rpy="0 -0 0" />
<geometry>
<box size="0.04 0.09 0.003" />
</geometry>
<material name="left_knee_1_1_u_side_femur_material">
<color rgba="0.301961 0.301961 0.301961 1.0"/>
</material>
</visual>
<inertial>
<origin xyz="-4.77564e-07 0.0488035 0.00148556" rpy="0 0 0"/>
<mass value="0.0288138"/>
<inertia ixx="1.85941e-05" ixy="4.56832e-10"  ixz="1.50205e-12" iyy="3.96313e-06" iyz="-1.91568e-08" izz="2.25143e-05" />
</inertial>
</link>
<joint name="left_knee_1_left_knee_1_1_u_side_femur_fixing" type="fixed">
<origin xyz="0 -0.0855 -0.003" rpy="2.8884e-32 3.94687e-31 2.46519e-32" />
<parent link="left_knee_1" />
<child link="left_knee_1_1_u_side_femur" />
<axis xyz="0 0 0"/>
</joint>

<link name="left_knee_1_2_u_side_femur_mir">
<collision>
<origin xyz="0 0.046 0.0445" rpy="0 -0 0" />
<geometry>
<box size="0.04 0.09 0.003" />
</geometry>
<material name="left_knee_1_2_u_side_femur_mir_material">
<color rgba="0.301961 0.301961 0.301961 1.0"/>
</material>
</collision>
<visual>
<origin xyz="0 0.046 0.0445" rpy="0 -0 0" />
<geometry>
<box size="0.04 0.09 0.003" />
</geometry>
<material name="left_knee_1_2_u_side_femur_mir_material">
<color rgba="0.301961 0.301961 0.301961 1.0"/>
</material>
</visual>
<inertial>
<origin xyz="4.77564e-07 0.0488035 0.0445144" rpy="0 0 0"/>
<mass value="0.0288138"/>
<inertia ixx="1.85941e-05" ixy="-4.56832e-10"  ixz="1.50205e-12" iyy="3.96313e-06" iyz="1.91568e-08" izz="2.25143e-05" />
</inertial>
</link>
<joint name="left_knee_1_left_knee_1_2_u_side_femur_mir_fixing" type="fixed">
<origin xyz="3.98986e-17 -0.0855 0.009" rpy="-1.43105e-16 2.90789e-16 5.55112e-17" />
<parent link="left_knee_1" />
<child link="left_knee_1_2_u_side_femur_mir" />
<axis xyz="0 0 0"/>
</joint>

<link name="left_knee_1_3_mx106">
<collision>
<origin xyz="0 -0.015 0" rpy="0 -0 0" />
<geometry>
<box size="0.03 0.055 0.04" />
</geometry>
<material name="left_knee_1_3_mx106_material">
<color rgba="0.301961 0.301961 0.301961 1.0"/>
</material>
</collision>
<visual>
<origin xyz="0 -0.015 0" rpy="0 -0 0" />
<geometry>
<box size="0.03 0.055 0.04" />
</geometry>
<material name="left_knee_1_3_mx106_material">
<color rgba="0.301961 0.301961 0.301961 1.0"/>
</material>
</visual>
<inertial>
<origin xyz="0 0 0.00254" rpy="0 0 0"/>
<mass value="0.158"/>
<inertia ixx="7.869e-05" ixy="-8.4e-07"  ixz="4.9e-07" iyy="4.097e-05" iyz="-9.14e-06" izz="6.136e-05" />
</inertial>
</link>
<joint name="left_knee_1_left_knee_1_3_mx106_fixing" type="fixed">
<origin xyz="-3.16414e-14 -0.14 0.026" rpy="3.14159 -5.29127e-17 -4.5397e-13" />
<parent link="left_knee_1" />
<child link="left_knee_1_3_mx106" />
<axis xyz="0 0 0"/>
</joint>

<link name="tibia_2">
<inertial>
<origin xyz="0 0 0" rpy="0 0 0" />
<mass value="1e-9" />
<inertia ixx="0" ixy="0" ixz="0" iyy="0" iyz="0" izz="0" />
</inertial>
</link>
<link name="tibia_2_0_tibia_plate">
<collision>
<origin xyz="0 -0.067 0.0015" rpy="0 -0 0" />
<geometry>
<box size="0.03 0.165 0.003" />
</geometry>
<material name="tibia_2_0_tibia_plate_material">
<color rgba="0.301961 0.301961 0.301961 1.0"/>
</material>
</collision>
<visual>
<origin xyz="0 -0.067 0.0015" rpy="0 -0 0" />
<geometry>
<box size="0.03 0.165 0.003" />
</geometry>
<material name="tibia_2_0_tibia_plate_material">
<color rgba="0.301961 0.301961 0.301961 1.0"/>
</material>
</visual>
<inertial>
<origin xyz="-0.00342169 -0.0646068 0.00149999" rpy="0 0 0"/>
<mass value="0.0444219"/>
<inertia ixx="8.90296e-05" ixy="3.06359e-06"  ixz="-7.21428e-12" iyy="4.7687e-06" iyz="1.9033e-11" izz="9.37317e-05" />
</inertial>
</link>
<joint name="tibia_2_tibia_2_0_tibia_plate_fixing" type="fixed">
<origin xyz="0 2.77556e-17 -0.003" rpy="-4.16539e-32 -2.96596e-31 4.49732e-30" />
<parent link="tibia_2" />
<child link="tibia_2_0_tibia_plate" />
<axis xyz="0 0 0"/>
</joint>

<link name="tibia_2_1_tibia_plate">
<collision>
<origin xyz="0 -0.067 0.0015" rpy="0 -0 0" />
<geometry>
<box size="0.03 0.165 0.003" />
</geometry>
<material name="tibia_2_1_tibia_plate_material">
<color rgba="0.301961 0.301961 0.301961 1.0"/>
</material>
</collision>
<visual>
<origin xyz="0 -0.067 0.0015" rpy="0 -0 0" />
<geometry>
<box size="0.03 0.165 0.003" />
</geometry>
<material name="tibia_2_1_tibia_plate_material">
<color rgba="0.301961 0.301961 0.301961 1.0"/>
</material>
</visual>
<inertial>
<origin xyz="-0.00342169 -0.0646068 0.00149999" rpy="0 0 0"/>
<mass value="0.0444219"/>
<inertia ixx="8.90296e-05" ixy="3.06359e-06"  ixz="-7.21428e-12" iyy="4.7687e-06" iyz="1.9033e-11" izz="9.37317e-05" />
</inertial>
</link>
<joint name="tibia_2_tibia_2_1_tibia_plate_fixing" type="fixed">
<origin xyz="0 0 0.052" rpy="-4.95589e-16 1.13809e-16 -1.96016e-15" />
<parent link="tibia_2" />
<child link="tibia_2_1_tibia_plate" />
<axis xyz="0 0 0"/>
</joint>

<link name="mx106_block_mir_2">
<inertial>
<origin xyz="0 0 0" rpy="0 0 0" />
<mass value="1e-9" />
<inertia ixx="0" ixy="0" ixz="0" iyy="0" iyz="0" izz="0" />
</inertial>
</link>
<link name="mx106_block_mir_2_0_mx106">
<collision>
<origin xyz="0 -0.015 0" rpy="0 -0 0" />
<geometry>
<box size="0.03 0.055 0.04" />
</geometry>
<material name="mx106_block_mir_2_0_mx106_material">
<color rgba="0.301961 0.301961 0.301961 1.0"/>
</material>
</collision>
<visual>
<origin xyz="0 -0.015 0" rpy="0 -0 0" />
<geometry>
<box size="0.03 0.055 0.04" />
</geometry>
<material name="mx106_block_mir_2_0_mx106_material">
<color rgba="0.301961 0.301961 0.301961 1.0"/>
</material>
</visual>
<inertial>
<origin xyz="0 0 0.00254" rpy="0 0 0"/>
<mass value="0.158"/>
<inertia ixx="7.869e-05" ixy="-8.4e-07"  ixz="4.9e-07" iyy="4.097e-05" iyz="-9.14e-06" izz="6.136e-05" />
</inertial>
</link>
<joint name="mx106_block_mir_2_mx106_block_mir_2_0_mx106_fixing" type="fixed">
<origin xyz="0 0 -0.026" rpy="0 -1.59332e-32 -5.04871e-29" />
<parent link="mx106_block_mir_2" />
<child link="mx106_block_mir_2_0_mx106" />
<axis xyz="0 0 0"/>
</joint>

<link name="mx106_block_mir_2_1_mx106">
<collision>
<origin xyz="0 -0.015 0" rpy="0 -0 0" />
<geometry>
<box size="0.03 0.055 0.04" />
</geometry>
<material name="mx106_block_mir_2_1_mx106_material">
<color rgba="0.301961 0.301961 0.301961 1.0"/>
</material>
</collision>
<visual>
<origin xyz="0 -0.015 0" rpy="0 -0 0" />
<geometry>
<box size="0.03 0.055 0.04" />
</geometry>
<material name="mx106_block_mir_2_1_mx106_material">
<color rgba="0.301961 0.301961 0.301961 1.0"/>
</material>
</visual>
<inertial>
<origin xyz="0 0 0.00254" rpy="0 0 0"/>
<mass value="0.158"/>
<inertia ixx="7.869e-05" ixy="-8.4e-07"  ixz="4.9e-07" iyy="4.097e-05" iyz="-9.14e-06" izz="6.136e-05" />
</inertial>
</link>
<joint name="mx106_block_mir_2_mx106_block_mir_2_1_mx106_fixing" type="fixed">
<origin xyz="-0.0494 -1.95954e-14 -0.026" rpy="-4.54891e-13 1.5708 0" />
<parent link="mx106_block_mir_2" />
<child link="mx106_block_mir_2_1_mx106" />
<axis xyz="0 0 0"/>
</joint>

<link name="left_foot_1">
<inertial>
<origin xyz="0 0 0" rpy="0 0 0" />
<mass value="1e-9" />
<inertia ixx="0" ixy="0" ixz="0" iyy="0" iyz="0" izz="0" />
</inertial>
</link>
<link name="left_foot_1_0_foot_protection">
<collision>
<origin xyz="-0.019 -0.0275 0.0125" rpy="0 0.785398 0" />
<geometry>
<box size="0.01 0.09 0.01" />
</geometry>
<material name="left_foot_1_0_foot_protection_material">
<color rgba="0.301961 0.290196 0.262745 1.0"/>
</material>
</collision>
<visual>
<origin xyz="-0.019 -0.0275 0.0125" rpy="0 0.785398 0" />
<geometry>
<box size="0.01 0.09 0.01" />
</geometry>
<material name="left_foot_1_0_foot_protection_material">
<color rgba="0.301961 0.290196 0.262745 1.0"/>
</material>
</visual>
<inertial>
<origin xyz="-0.00751487 -0.0275 0.0127382" rpy="0 0 0"/>
<mass value="0.0434827"/>
<inertia ixx="1.82682e-05" ixy="0"  ixz="-1.2295e-06" iyy="9.28949e-06" iyz="0" izz="2.43902e-05" />
</inertial>
</link>
<joint name="left_foot_1_left_foot_1_0_foot_protection_fixing" type="fixed">
<origin xyz="-0.022 -0.04 0.10347" rpy="-1.5708 1.5708 0" />
<parent link="left_foot_1" />
<child link="left_foot_1_0_foot_protection" />
<axis xyz="0 0 0"/>
</joint>

<link name="left_foot_cleat_back_left">
<collision>
<origin xyz="0 0.01 0" rpy="1.5708 -0 0" />
<geometry>
<cylinder length="0.02" radius="0.008" />
</geometry>
<material name="left_foot_cleat_back_left_material">
<color rgba="0.301961 0.290196 0.262745 1.0"/>
</material>
</collision>
<visual>
<origin xyz="0 0.01 0" rpy="1.5708 -0 0" />
<geometry>
<cylinder length="0.02" radius="0.008" />
</geometry>
<material name="left_foot_cleat_back_left_material">
<color rgba="0.301961 0.290196 0.262745 1.0"/>
</material>
</visual>
<inertial>
<origin xyz="4.88654e-18 0.00894735 -1.23609e-35" rpy="0 0 0"/>
<mass value="0.00284785"/>
<inertia ixx="9.93965e-08" ixy="0"  ixz="0" iyy="8.64315e-08" iyz="0" izz="9.93965e-08" />
</inertial>
</link>
<joint name="left_foot_1_left_foot_cleat_back_left_fixing" type="fixed">
<origin xyz="0.0435 -0.06 -0.03213" rpy="3.14159 0.480536 3.14159" />
<parent link="left_foot_1" />
<child link="left_foot_cleat_back_left" />
<axis xyz="0 0 0"/>
</joint>

<link name="left_foot_1_2_u_side_small">
<collision>
<origin xyz="0.015 0.023 0.0015" rpy="0 -0 0" />
<geometry>
<box size="0.025 0.044 0.003" />
</geometry>
<material name="left_foot_1_2_u_side_small_material">
<color rgba="0.301961 0.301961 0.301961 1.0"/>
</material>
</collision>
<visual>
<origin xyz="0.015 0.023 0.0015" rpy="0 -0 0" />
<geometry>
<box size="0.025 0.044 0.003" />
</geometry>
<material name="left_foot_1_2_u_side_small_material">
<color rgba="0.301961 0.301961 0.301961 1.0"/>
</material>
</visual>
<inertial>
<origin xyz="0.015 0.0221162 0.00145795" rpy="0 0 0"/>
<mass value="0.00960981"/>
<inertia ixx="1.4711e-06" ixy="1.8235e-13"  ixz="-1.13892e-14" iyy="7.29209e-07" iyz="-7.82613e-09" izz="2.1862e-06" />
</inertial>
</link>
<joint name="left_foot_1_left_foot_1_2_u_side_small_fixing" type="fixed">
<origin xyz="0.015 -0.04 0.05634" rpy="-3.14159 -3.72098e-16 -3.14159" />
<parent link="left_foot_1" />
<child link="left_foot_1_2_u_side_small" />
<axis xyz="0 0 0"/>
</joint>

<link name="left_foot_cleat_front_left">
<collision>
<origin xyz="0 0.01 0" rpy="1.5708 -0 0" />
<geometry>
<cylinder length="0.02" radius="0.008" />
</geometry>
<material name="left_foot_cleat_front_left_material">
<color rgba="0.301961 0.290196 0.262745 1.0"/>
</material>
</collision>
<visual>
<origin xyz="0 0.01 0" rpy="1.5708 -0 0" />
<geometry>
<cylinder length="0.02" radius="0.008" />
</geometry>
<material name="left_foot_cleat_front_left_material">
<color rgba="0.301961 0.290196 0.262745 1.0"/>
</material>
</visual>
<inertial>
<origin xyz="4.88654e-18 0.00894735 -1.23609e-35" rpy="0 0 0"/>
<mass value="0.00284785"/>
<inertia ixx="9.93965e-08" ixy="0"  ixz="0" iyy="8.64315e-08" iyz="0" izz="9.93965e-08" />
</inertial>
</link>
<joint name="left_foot_1_left_foot_cleat_front_left_fixing" type="fixed">
<origin xyz="0.0435 -0.06 0.10947" rpy="3.14159 0.480536 3.14159" />
<parent link="left_foot_1" />
<child link="left_foot_cleat_front_left" />
<axis xyz="0 0 0"/>
</joint>

<link name="left_foot_1_4_u_base_motors_blocs">
<collision>
<origin xyz="0.026 0.015 0.003" rpy="0 -0 0" />
<geometry>
<box size="0.05 0.03 0.006" />
</geometry>
<material name="left_foot_1_4_u_base_motors_blocs_material">
<color rgba="0.301961 0.301961 0.301961 1.0"/>
</material>
</collision>
<visual>
<origin xyz="0.026 0.015 0.003" rpy="0 -0 0" />
<geometry>
<box size="0.05 0.03 0.006" />
</geometry>
<material name="left_foot_1_4_u_base_motors_blocs_material">
<color rgba="0.301961 0.301961 0.301961 1.0"/>
</material>
</visual>
<inertial>
<origin xyz="0.0258184 0.015 0.00240855" rpy="0 0 0"/>
<mass value="0.0177728"/>
<inertia ixx="1.53307e-06" ixy="0"  ixz="-2.55301e-09" iyy="4.59364e-06" iyz="0" izz="6.04516e-06" />
</inertial>
</link>
<joint name="left_foot_1_left_foot_1_4_u_base_motors_blocs_fixing" type="fixed">
<origin xyz="0.015 -0.04 0.05434" rpy="-1.5708 1.5708 0" />
<parent link="left_foot_1" />
<child link="left_foot_1_4_u_base_motors_blocs" />
<axis xyz="0 0 0"/>
</joint>

<link name="left_foot_cleat_front_right">
<collision>
<origin xyz="0 0.01 0" rpy="1.5708 -0 0" />
<geometry>
<cylinder length="0.02" radius="0.008" />
</geometry>
<material name="left_foot_cleat_front_right_material">
<color rgba="0.301961 0.290196 0.262745 1.0"/>
</material>
</collision>
<visual>
<origin xyz="0 0.01 0" rpy="1.5708 -0 0" />
<geometry>
<cylinder length="0.02" radius="0.008" />
</geometry>
<material name="left_foot_cleat_front_right_material">
<color rgba="0.301961 0.290196 0.262745 1.0"/>
</material>
</visual>
<inertial>
<origin xyz="4.88654e-18 0.00894735 -1.23609e-35" rpy="0 0 0"/>
<mass value="0.00284785"/>
<inertia ixx="9.93965e-08" ixy="0"  ixz="0" iyy="8.64315e-08" iyz="0" izz="9.93965e-08" />
</inertial>
</link>
<joint name="left_foot_1_left_foot_cleat_front_right_fixing" type="fixed">
<origin xyz="-0.0325 -0.06 0.10947" rpy="3.14159 0.480536 3.14159" />
<parent link="left_foot_1" />
<child link="left_foot_cleat_front_right" />
<axis xyz="0 0 0"/>
</joint>

<link name="left_foot_cleat_back_right">
<collision>
<origin xyz="0 0.01 0" rpy="1.5708 -0 0" />
<geometry>
<cylinder length="0.02" radius="0.008" />
</geometry>
<material name="left_foot_cleat_back_right_material">
<color rgba="0.301961 0.290196 0.262745 1.0"/>
</material>
</collision>
<visual>
<origin xyz="0 0.01 0" rpy="1.5708 -0 0" />
<geometry>
<cylinder length="0.02" radius="0.008" />
</geometry>
<material name="left_foot_cleat_back_right_material">
<color rgba="0.301961 0.290196 0.262745 1.0"/>
</material>
</visual>
<inertial>
<origin xyz="4.88654e-18 0.00894735 -1.23609e-35" rpy="0 0 0"/>
<mass value="0.00284785"/>
<inertia ixx="9.93965e-08" ixy="0"  ixz="0" iyy="8.64315e-08" iyz="0" izz="9.93965e-08" />
</inertial>
</link>
<joint name="left_foot_1_left_foot_cleat_back_right_fixing" type="fixed">
<origin xyz="-0.0325 -0.06 -0.03213" rpy="3.14159 0.480536 -3.14159" />
<parent link="left_foot_1" />
<child link="left_foot_cleat_back_right" />
<axis xyz="0 0 0"/>
</joint>

<link name="left_foot_1_7_u_side_small_with_trace">
<collision>
<origin xyz="0.015 0.023 0.0015" rpy="0 -0 0" />
<geometry>
<box size="0.027 0.042 0.003" />
</geometry>
<material name="left_foot_1_7_u_side_small_with_trace_material">
<color rgba="0.301961 0.301961 0.301961 1.0"/>
</material>
</collision>
<visual>
<origin xyz="0.015 0.023 0.0015" rpy="0 -0 0" />
<geometry>
<box size="0.027 0.042 0.003" />
</geometry>
<material name="left_foot_1_7_u_side_small_with_trace_material">
<color rgba="0.301961 0.301961 0.301961 1.0"/>
</material>
</visual>
<inertial>
<origin xyz="0.015 0.0200591 0.00125723" rpy="0 0 0"/>
<mass value="0.00805776"/>
<inertia ixx="1.17632e-06" ixy="1.41838e-13"  ixz="7.6877e-14" iyy="6.21461e-07" iyz="1.27729e-08" izz="1.78795e-06" />
</inertial>
</link>
<joint name="left_foot_1_left_foot_1_7_u_side_small_with_trace_fixing" type="fixed">
<origin xyz="-0.015 -0.04 0" rpy="-1.01204e-28 1.00954e-31 -1.35585e-31" />
<parent link="left_foot_1" />
<child link="left_foot_1_7_u_side_small_with_trace" />
<axis xyz="0 0 0"/>
</joint>

<link name="left_foot_1_8_foot_plate">
<collision>
<origin xyz="0 0 0.0015" rpy="0 -0 0" />
<geometry>
<box size="0.09 0.155 0.003" />
</geometry>
<material name="left_foot_1_8_foot_plate_material">
<color rgba="0.301961 0.301961 0.301961 1.0"/>
</material>
</collision>
<visual>
<origin xyz="0 0 0.0015" rpy="0 -0 0" />
<geometry>
<box size="0.09 0.155 0.003" />
</geometry>
<material name="left_foot_1_8_foot_plate_material">
<color rgba="0.301961 0.301961 0.301961 1.0"/>
</material>
</visual>
<inertial>
<origin xyz="6.4782e-18 0.00163454 0.0015" rpy="0 0 0"/>
<mass value="0.10146"/>
<inertia ixx="0.00020829" ixy="0"  ixz="0" iyy="7.17162e-05" iyz="0" izz="0.000279854" />
</inertial>
</link>
<joint name="left_foot_1_left_foot_1_8_foot_plate_fixing" type="fixed">
<origin xyz="0.0055 -0.043 0.03867" rpy="1.5708 5.25446e-16 -3.14159" />
<parent link="left_foot_1" />
<child link="left_foot_1_8_foot_plate" />
<axis xyz="0 0 0"/>
</joint>

<link name="left_foot">
<inertial>
<origin xyz="0 0 0" rpy="0 0 0" />
<mass value="1e-9" />
<inertia ixx="0" ixy="0" ixz="0" iyy="0" iyz="0" izz="0" />
</inertial>
</link>
<joint name="left_foot_frame" type="fixed">
<origin xyz="-2.498e-16 -0.06 0.02317" rpy="-1.5708 -1.5708 0" />
<parent link="left_foot_1" />
<child link="left_foot" />
<axis xyz="0 0 0"/>
</joint>

<joint name="left_ankle_roll" type="revolute">
<origin xyz="-0.0234 -7.77156e-15 -0.026" rpy="-3.14159 -1.5708 0" />
<parent link="mx106_block_mir_2" />
<child link="left_foot_1" />
<axis xyz="-0 -0 1"/>
<limit effort="10" velocity="6" />
<joint_properties friction="0.0"/>
</joint>

<joint name="left_ankle_pitch" type="revolute">
<origin xyz="1.38778e-17 -0.14 1.38778e-17" rpy="3.14159 1.02268e-16 3.112e-16" />
<parent link="tibia_2" />
<child link="mx106_block_mir_2" />
<axis xyz="0 0 1"/>
<limit effort="10" velocity="6" />
<joint_properties friction="0.0"/>
</joint>

<joint name="left_knee" type="revolute">
<origin xyz="-3.16344e-14 -0.14 -1.99285e-14" rpy="-3.23307e-16 -1.07858e-16 -4.52629e-13" />
<parent link="left_knee_1" />
<child link="tibia_2" />
<axis xyz="-0 -0 -1"/>
<limit effort="10" velocity="6" />
<joint_properties friction="0.0"/>
</joint>

<joint name="left_hip_pitch" type="revolute">
<origin xyz="0.026 1.24623e-14 0.0234" rpy="2.88373e-13 -1.5708 0" />
<parent link="mx106_block_2" />
<child link="left_knee_1" />
<axis xyz="-0 -0 -1"/>
<limit effort="10" velocity="6" />
<joint_properties friction="0.0"/>
</joint>

<joint name="left_hip_roll" type="revolute">
<origin xyz="0.0234 0 0.04" rpy="-1.5708 -2.8828e-13 1.5708" />
<parent link="u_block_2" />
<child link="mx106_block_2" />
<axis xyz="0 0 1"/>
<limit effort="10" velocity="6" />
<joint_properties friction="0.0"/>
</joint>

<joint name="left_hip_yaw" type="revolute">
<origin xyz="0.046375 -0.010627 -0.0035" rpy="-3.14159 -3.15386e-16 1.5708" />
<parent link="trunk_1" />
<child link="u_block_2" />
<axis xyz="0 0 -1"/>
<limit effort="10" velocity="6" />
<joint_properties friction="0.0"/>
</joint>

<link name="u_shoulder_1">
<inertial>
<origin xyz="0 0 0" rpy="0 0 0" />
<mass value="1e-9" />
<inertia ixx="0" ixy="0" ixz="0" iyy="0" iyz="0" izz="0" />
</inertial>
</link>
<link name="u_shoulder_1_0_u_side_shoulder">
<inertial>
<origin xyz="0.0240325 0.00804746 0.0261774" rpy="0 0 0"/>
<mass value="0.0129542"/>
<inertia ixx="3.94264e-06" ixy="3.39157e-09"  ixz="9.80835e-09" iyy="1.92581e-06" iyz="-9.01323e-07" izz="2.03652e-06" />
</inertial>
</link>
<joint name="u_shoulder_1_u_shoulder_1_0_u_side_shoulder_fixing" type="fixed">
<origin xyz="0 -2.77556e-17 1.38778e-17" rpy="7.14618e-16 7.51966e-31 2.77556e-16" />
<parent link="u_shoulder_1" />
<child link="u_shoulder_1_0_u_side_shoulder" />
<axis xyz="0 0 0"/>
</joint>

<link name="u_shoulder_1_1_u_side_shoulder_mir">
<inertial>
<origin xyz="0.0469675 0.00804746 0.0261774" rpy="0 0 0"/>
<mass value="0.0129542"/>
<inertia ixx="3.94264e-06" ixy="-3.39157e-09"  ixz="-9.80835e-09" iyy="1.92581e-06" iyz="-9.01323e-07" izz="2.03652e-06" />
</inertial>
</link>
<joint name="u_shoulder_1_u_shoulder_1_1_u_side_shoulder_mir_fixing" type="fixed">
<origin xyz="-0.071 -5.55112e-17 0" rpy="-6.07076e-16 7.51966e-31 2.77556e-16" />
<parent link="u_shoulder_1" />
<child link="u_shoulder_1_1_u_side_shoulder_mir" />
<axis xyz="0 0 0"/>
</joint>

<link name="u_shoulder_1_2_u_base_64">
<collision>
<origin xyz="0 0 0.003" rpy="0 -0 0" />
<geometry>
<box size="0.047 0.0275 0.006" />
</geometry>
<material name="u_shoulder_1_2_u_base_64_material">
<color rgba="0.301961 0.301961 0.301961 1.0"/>
</material>
</collision>
<visual>
<origin xyz="0 0 0.003" rpy="0 -0 0" />
<geometry>
<box size="0.047 0.0275 0.006" />
</geometry>
<material name="u_shoulder_1_2_u_base_64_material">
<color rgba="0.301961 0.301961 0.301961 1.0"/>
</material>
</visual>
<inertial>
<origin xyz="1.1674e-18 4.63685e-18 0.0024567" rpy="0 0 0"/>
<mass value="0.0169896"/>
<inertia ixx="1.47574e-06" ixy="0"  ixz="0" iyy="3.90938e-06" iyz="0" izz="5.30237e-06" />
</inertial>
</link>
<joint name="u_shoulder_1_u_shoulder_1_2_u_base_64_fixing" type="fixed">
<origin xyz="0 -2.77556e-17 0" rpy="-7.72656e-34 7.6689e-31 2.21867e-31" />
<parent link="u_shoulder_1" />
<child link="u_shoulder_1_2_u_base_64" />
<axis xyz="0 0 0"/>
</joint>

<link name="left_humerus_1">
<inertial>
<origin xyz="0 0 0" rpy="0 0 0" />
<mass value="1e-9" />
<inertia ixx="0" ixy="0" ixz="0" iyy="0" iyz="0" izz="0" />
</inertial>
</link>
<link name="left_humerus_1_0_mx64">
<collision>
<origin xyz="0 -0.015 0" rpy="0 -0 0" />
<geometry>
<box size="0.029 0.05 0.04" />
</geometry>
<material name="left_humerus_1_0_mx64_material">
<color rgba="0.211765 0.211765 0.211765 1.0"/>
</material>
</collision>
<visual>
<origin xyz="0 -0.015 0" rpy="0 -0 0" />
<geometry>
<box size="0.029 0.05 0.04" />
</geometry>
<material name="left_humerus_1_0_mx64_material">
<color rgba="0.211765 0.211765 0.211765 1.0"/>
</material>
</visual>
<inertial>
<origin xyz="0 0 0.00254" rpy="0 0 0"/>
<mass value="0.158"/>
<inertia ixx="7.869e-05" ixy="-8.4e-07"  ixz="4.9e-07" iyy="4.097e-05" iyz="-9.14e-06" izz="6.136e-05" />
</inertial>
</link>
<joint name="left_humerus_1_left_humerus_1_0_mx64_fixing" type="fixed">
<origin xyz="0 0 -0.0235" rpy="-3.69779e-32 5.7326e-32 1.84671e-33" />
<parent link="left_humerus_1" />
<child link="left_humerus_1_0_mx64" />
<axis xyz="0 0 0"/>
</joint>

<link name="left_humerus_1_1_humerus_plate">
<collision>
<origin xyz="0.0015 0.035 0.015" rpy="0 -0 0" />
<geometry>
<box size="0.003 0.07 0.03" />
</geometry>
<material name="left_humerus_1_1_humerus_plate_material">
<color rgba="0.301961 0.301961 0.301961 1.0"/>
</material>
</collision>
<collision>
<origin xyz="0.0175 0.073 0.015" rpy="0 -0 0" />
<geometry>
<box size="0.03 0.003 0.03" />
</geometry>
<material name="left_humerus_1_1_humerus_plate_material">
<color rgba="0.301961 0.301961 0.301961 1.0"/>
</material>
</collision>
<visual>
<origin xyz="0.0015 0.035 0.015" rpy="0 -0 0" />
<geometry>
<box size="0.003 0.07 0.03" />
</geometry>
<material name="left_humerus_1_1_humerus_plate_material">
<color rgba="0.301961 0.301961 0.301961 1.0"/>
</material>
</visual>
<visual>
<origin xyz="0.0175 0.073 0.015" rpy="0 -0 0" />
<geometry>
<box size="0.03 0.003 0.03" />
</geometry>
<material name="left_humerus_1_1_humerus_plate_material">
<color rgba="0.301961 0.301961 0.301961 1.0"/>
</material>
</visual>
<inertial>
<origin xyz="0.00589152 0.0473648 0.015" rpy="0 0 0"/>
<mass value="0.0250329"/>
<inertia ixx="1.65885e-05" ixy="-2.87306e-06"  ixz="0" iyy="3.63732e-06" iyz="0" izz="1.64692e-05" />
</inertial>
</link>
<joint name="left_humerus_1_left_humerus_1_1_humerus_plate_fixing" type="fixed">
<origin xyz="0.015 -0.127 -0.0406736" rpy="3.45444e-16 -1.5708 0" />
<parent link="left_humerus_1" />
<child link="left_humerus_1_1_humerus_plate" />
<axis xyz="0 0 0"/>
</joint>

<link name="left_radius_1">
<inertial>
<origin xyz="0 0 0" rpy="0 0 0" />
<mass value="1e-9" />
<inertia ixx="0" ixy="0" ixz="0" iyy="0" iyz="0" izz="0" />
</inertial>
</link>
<link name="left_radius_1_0_mx64">
<collision>
<origin xyz="0 -0.015 0" rpy="0 -0 0" />
<geometry>
<box size="0.029 0.05 0.04" />
</geometry>
<material name="left_radius_1_0_mx64_material">
<color rgba="0.211765 0.211765 0.211765 1.0"/>
</material>
</collision>
<visual>
<origin xyz="0 -0.015 0" rpy="0 -0 0" />
<geometry>
<box size="0.029 0.05 0.04" />
</geometry>
<material name="left_radius_1_0_mx64_material">
<color rgba="0.211765 0.211765 0.211765 1.0"/>
</material>
</visual>
<inertial>
<origin xyz="0 0 0.00254" rpy="0 0 0"/>
<mass value="0.158"/>
<inertia ixx="7.869e-05" ixy="-8.4e-07"  ixz="4.9e-07" iyy="4.097e-05" iyz="-9.14e-06" izz="6.136e-05" />
</inertial>
</link>
<joint name="left_radius_1_left_radius_1_0_mx64_fixing" type="fixed">
<origin xyz="0 0 -0.0235" rpy="2.98462e-31 -6.96352e-30 4.98955e-29" />
<parent link="left_radius_1" />
<child link="left_radius_1_0_mx64" />
<axis xyz="0 0 0"/>
</joint>

<link name="left_radius_1_1_radius_plate">
<collision>
<origin xyz="-0.0015 0.0425 0.015" rpy="0 -0 0" />
<geometry>
<box size="0.003 0.085 0.03" />
</geometry>
<material name="left_radius_1_1_radius_plate_material">
<color rgba="0.301961 0.301961 0.301961 1.0"/>
</material>
</collision>
<collision>
<origin xyz="0.009 0 0.015" rpy="0 -0 0" />
<geometry>
<cylinder length="0.03" radius="0.012" />
</geometry>
<material name="left_radius_1_1_radius_plate_material">
<color rgba="0.301961 0.301961 0.301961 1.0"/>
</material>
</collision>
<visual>
<origin xyz="-0.0015 0.0425 0.015" rpy="0 -0 0" />
<geometry>
<box size="0.003 0.085 0.03" />
</geometry>
<material name="left_radius_1_1_radius_plate_material">
<color rgba="0.301961 0.301961 0.301961 1.0"/>
</material>
</visual>
<visual>
<origin xyz="0.009 0 0.015" rpy="0 -0 0" />
<geometry>
<cylinder length="0.03" radius="0.012" />
</geometry>
<material name="left_radius_1_1_radius_plate_material">
<color rgba="0.301961 0.301961 0.301961 1.0"/>
</material>
</visual>
<inertial>
<origin xyz="0.00541212 0.0382454 0.015" rpy="0 0 0"/>
<mass value="0.0420009"/>
<inertia ixx="5.74704e-05" ixy="-3.5136e-07"  ixz="0" iyy="6.75001e-06" iyz="0" izz="5.79253e-05" />
</inertial>
</link>
<joint name="left_radius_1_left_radius_1_1_radius_plate_fixing" type="fixed">
<origin xyz="0.0165 -0.141 -0.0085" rpy="-3.14159 -1.63297e-15 3.14159" />
<parent link="left_radius_1" />
<child link="left_radius_1_1_radius_plate" />
<axis xyz="0 0 0"/>
</joint>

<joint name="left_elbow" type="revolute">
<origin xyz="0.0235 -0.112 -0.00167365" rpy="4.539e-13 1.5708 0" />
<parent link="left_humerus_1" />
<child link="left_radius_1" />
<axis xyz="0 0 1"/>
<limit effort="10" velocity="6" />
<joint_properties friction="0.0"/>
</joint>

<joint name="left_shoulder_roll" type="revolute">
<origin xyz="0.0225 0.03 0.035" rpy="-3.14159 -1.5708 0" />
<parent link="u_shoulder_1" />
<child link="left_humerus_1" />
<axis xyz="0 0 1"/>
<limit effort="10" velocity="6" />
<joint_properties friction="0.0"/>
</joint>

<joint name="left_shoulder_pitch" type="revolute">
<origin xyz="0.0735 -0.0315 0.1609" rpy="-1.5708 -4.55247e-13 -1.5708" />
<parent link="trunk_1" />
<child link="u_shoulder_1" />
<axis xyz="-0 -0 1"/>
<limit effort="10" velocity="6" />
<joint_properties friction="0.0"/>
</joint>

<link name="u_shoulder_2">
<inertial>
<origin xyz="0 0 0" rpy="0 0 0" />
<mass value="1e-9" />
<inertia ixx="0" ixy="0" ixz="0" iyy="0" iyz="0" izz="0" />
</inertial>
</link>
<link name="u_shoulder_2_0_u_side_shoulder_mir">
<inertial>
<origin xyz="0.0469675 0.00804746 0.0261774" rpy="0 0 0"/>
<mass value="0.0129542"/>
<inertia ixx="3.94264e-06" ixy="-3.39157e-09"  ixz="-9.80835e-09" iyy="1.92581e-06" iyz="-9.01323e-07" izz="2.03652e-06" />
</inertial>
</link>
<joint name="u_shoulder_2_u_shoulder_2_0_u_side_shoulder_mir_fixing" type="fixed">
<origin xyz="-0.071 -5.55112e-17 -1.38778e-17" rpy="-6.25868e-16 -2.9771e-29 3.46945e-16" />
<parent link="u_shoulder_2" />
<child link="u_shoulder_2_0_u_side_shoulder_mir" />
<axis xyz="0 0 0"/>
</joint>

<link name="u_shoulder_2_1_u_base_64">
<collision>
<origin xyz="0 0 0.003" rpy="0 -0 0" />
<geometry>
<box size="0.047 0.0275 0.006" />
</geometry>
<material name="u_shoulder_2_1_u_base_64_material">
<color rgba="0.301961 0.301961 0.301961 1.0"/>
</material>
</collision>
<visual>
<origin xyz="0 0 0.003" rpy="0 -0 0" />
<geometry>
<box size="0.047 0.0275 0.006" />
</geometry>
<material name="u_shoulder_2_1_u_base_64_material">
<color rgba="0.301961 0.301961 0.301961 1.0"/>
</material>
</visual>
<inertial>
<origin xyz="1.1674e-18 4.63685e-18 0.0024567" rpy="0 0 0"/>
<mass value="0.0169896"/>
<inertia ixx="1.47574e-06" ixy="0"  ixz="0" iyy="3.90938e-06" iyz="0" izz="5.30237e-06" />
</inertial>
</link>
<joint name="u_shoulder_2_u_shoulder_2_1_u_base_64_fixing" type="fixed">
<origin xyz="0 -2.77556e-17 0" rpy="1.35105e-33 -4.53958e-30 -5.25394e-31" />
<parent link="u_shoulder_2" />
<child link="u_shoulder_2_1_u_base_64" />
<axis xyz="0 0 0"/>
</joint>

<link name="u_shoulder_2_2_u_side_shoulder">
<inertial>
<origin xyz="0.0240325 0.00804746 0.0261774" rpy="0 0 0"/>
<mass value="0.0129542"/>
<inertia ixx="3.94264e-06" ixy="3.39157e-09"  ixz="9.80835e-09" iyy="1.92581e-06" iyz="-9.01323e-07" izz="2.03652e-06" />
</inertial>
</link>
<joint name="u_shoulder_2_u_shoulder_2_2_u_side_shoulder_fixing" type="fixed">
<origin xyz="-6.93889e-18 -2.77556e-17 0" rpy="6.95826e-16 -4.23928e-29 3.46945e-16" />
<parent link="u_shoulder_2" />
<child link="u_shoulder_2_2_u_side_shoulder" />
<axis xyz="0 0 0"/>
</joint>

<link name="right_humerus_1">
<inertial>
<origin xyz="0 0 0" rpy="0 0 0" />
<mass value="1e-9" />
<inertia ixx="0" ixy="0" ixz="0" iyy="0" iyz="0" izz="0" />
</inertial>
</link>
<link name="right_humerus_1_0_humerus_plate">
<collision>
<origin xyz="0.0015 0.035 0.015" rpy="0 -0 0" />
<geometry>
<box size="0.003 0.07 0.03" />
</geometry>
<material name="right_humerus_1_0_humerus_plate_material">
<color rgba="0.301961 0.301961 0.301961 1.0"/>
</material>
</collision>
<collision>
<origin xyz="0.0175 0.073 0.015" rpy="0 -0 0" />
<geometry>
<box size="0.03 0.003 0.03" />
</geometry>
<material name="right_humerus_1_0_humerus_plate_material">
<color rgba="0.301961 0.301961 0.301961 1.0"/>
</material>
</collision>
<visual>
<origin xyz="0.0015 0.035 0.015" rpy="0 -0 0" />
<geometry>
<box size="0.003 0.07 0.03" />
</geometry>
<material name="right_humerus_1_0_humerus_plate_material">
<color rgba="0.301961 0.301961 0.301961 1.0"/>
</material>
</visual>
<visual>
<origin xyz="0.0175 0.073 0.015" rpy="0 -0 0" />
<geometry>
<box size="0.03 0.003 0.03" />
</geometry>
<material name="right_humerus_1_0_humerus_plate_material">
<color rgba="0.301961 0.301961 0.301961 1.0"/>
</material>
</visual>
<inertial>
<origin xyz="0.00589152 0.0473648 0.015" rpy="0 0 0"/>
<mass value="0.0250329"/>
<inertia ixx="1.65885e-05" ixy="-2.87306e-06"  ixz="0" iyy="3.63732e-06" iyz="0" izz="1.64692e-05" />
</inertial>
</link>
<joint name="right_humerus_1_right_humerus_1_0_humerus_plate_fixing" type="fixed">
<origin xyz="0.015 -0.127 -0.0415" rpy="-4.54407e-13 -1.5708 0" />
<parent link="right_humerus_1" />
<child link="right_humerus_1_0_humerus_plate" />
<axis xyz="0 0 0"/>
</joint>

<link name="right_humerus_1_1_mx64">
<collision>
<origin xyz="0 -0.015 0" rpy="0 -0 0" />
<geometry>
<box size="0.029 0.05 0.04" />
</geometry>
<material name="right_humerus_1_1_mx64_material">
<color rgba="0.211765 0.211765 0.211765 1.0"/>
</material>
</collision>
<visual>
<origin xyz="0 -0.015 0" rpy="0 -0 0" />
<geometry>
<box size="0.029 0.05 0.04" />
</geometry>
<material name="right_humerus_1_1_mx64_material">
<color rgba="0.211765 0.211765 0.211765 1.0"/>
</material>
</visual>
<inertial>
<origin xyz="0 0 0.00254" rpy="0 0 0"/>
<mass value="0.158"/>
<inertia ixx="7.869e-05" ixy="-8.4e-07"  ixz="4.9e-07" iyy="4.097e-05" iyz="-9.14e-06" izz="6.136e-05" />
</inertial>
</link>
<joint name="right_humerus_1_right_humerus_1_1_mx64_fixing" type="fixed">
<origin xyz="0 -2.77556e-17 -0.0235" rpy="4.14075e-32 -4.9864e-30 -4.62223e-33" />
<parent link="right_humerus_1" />
<child link="right_humerus_1_1_mx64" />
<axis xyz="0 0 0"/>
</joint>

<link name="right_radius_1">
<inertial>
<origin xyz="0 0 0" rpy="0 0 0" />
<mass value="1e-9" />
<inertia ixx="0" ixy="0" ixz="0" iyy="0" iyz="0" izz="0" />
</inertial>
</link>
<link name="right_radius_1_0_radius_plate">
<collision>
<origin xyz="-0.0015 0.0425 0.015" rpy="0 -0 0" />
<geometry>
<box size="0.003 0.085 0.03" />
</geometry>
<material name="right_radius_1_0_radius_plate_material">
<color rgba="0.301961 0.301961 0.301961 1.0"/>
</material>
</collision>
<collision>
<origin xyz="0.009 0 0.015" rpy="0 -0 0" />
<geometry>
<cylinder length="0.03" radius="0.012" />
</geometry>
<material name="right_radius_1_0_radius_plate_material">
<color rgba="0.301961 0.301961 0.301961 1.0"/>
</material>
</collision>
<visual>
<origin xyz="-0.0015 0.0425 0.015" rpy="0 -0 0" />
<geometry>
<box size="0.003 0.085 0.03" />
</geometry>
<material name="right_radius_1_0_radius_plate_material">
<color rgba="0.301961 0.301961 0.301961 1.0"/>
</material>
</visual>
<visual>
<origin xyz="0.009 0 0.015" rpy="0 -0 0" />
<geometry>
<cylinder length="0.03" radius="0.012" />
</geometry>
<material name="right_radius_1_0_radius_plate_material">
<color rgba="0.301961 0.301961 0.301961 1.0"/>
</material>
</visual>
<inertial>
<origin xyz="0.00541212 0.0382454 0.015" rpy="0 0 0"/>
<mass value="0.0420009"/>
<inertia ixx="5.74704e-05" ixy="-3.5136e-07"  ixz="0" iyy="6.75001e-06" iyz="0" izz="5.79253e-05" />
</inertial>
</link>
<joint name="right_radius_1_right_radius_1_0_radius_plate_fixing" type="fixed">
<origin xyz="-0.0165 -0.141 -0.0385" rpy="2.95826e-16 1.82781e-15 2.61184e-16" />
<parent link="right_radius_1" />
<child link="right_radius_1_0_radius_plate" />
<axis xyz="0 0 0"/>
</joint>

<link name="right_radius_1_1_mx64">
<collision>
<origin xyz="0 -0.015 0" rpy="0 -0 0" />
<geometry>
<box size="0.029 0.05 0.04" />
</geometry>
<material name="right_radius_1_1_mx64_material">
<color rgba="0.211765 0.211765 0.211765 1.0"/>
</material>
</collision>
<visual>
<origin xyz="0 -0.015 0" rpy="0 -0 0" />
<geometry>
<box size="0.029 0.05 0.04" />
</geometry>
<material name="right_radius_1_1_mx64_material">
<color rgba="0.211765 0.211765 0.211765 1.0"/>
</material>
</visual>
<inertial>
<origin xyz="0 0 0.00254" rpy="0 0 0"/>
<mass value="0.158"/>
<inertia ixx="7.869e-05" ixy="-8.4e-07"  ixz="4.9e-07" iyy="4.097e-05" iyz="-9.14e-06" izz="6.136e-05" />
</inertial>
</link>
<joint name="right_radius_1_right_radius_1_1_mx64_fixing" type="fixed">
<origin xyz="0 3.46945e-18 -0.0235" rpy="-8.78202e-31 -2.02341e-30 -3.55576e-32" />
<parent link="right_radius_1" />
<child link="right_radius_1_1_mx64" />
<axis xyz="0 0 0"/>
</joint>

<joint name="right_elbow" type="revolute">
<origin xyz="-0.0235 -0.112 -0.0025" rpy="-9.07649e-13 -1.5708 0" />
<parent link="right_humerus_1" />
<child link="right_radius_1" />
<axis xyz="-0 -0 -1"/>
<limit effort="10" velocity="6" />
<joint_properties friction="0.0"/>
</joint>

<joint name="right_shoulder_roll" type="revolute">
<origin xyz="-0.0225 0.03 0.035" rpy="3.14159 1.5708 0" />
<parent link="u_shoulder_2" />
<child link="right_humerus_1" />
<axis xyz="0 0 1"/>
<limit effort="10" velocity="6" />
<joint_properties friction="0.0"/>
</joint>

<joint name="right_shoulder_pitch" type="revolute">
<origin xyz="-0.0740868 -0.0315 0.1609" rpy="-1.5708 -2.17187e-15 1.5708" />
<parent link="trunk_1" />
<child link="u_shoulder_2" />
<axis xyz="0 0 -1"/>
<limit effort="10" velocity="6" />
<joint_properties friction="0.0"/>
</joint>

<link name="u_neck_1">
<inertial>
<origin xyz="0 0 0" rpy="0 0 0" />
<mass value="1e-9" />
<inertia ixx="0" ixy="0" ixz="0" iyy="0" iyz="0" izz="0" />
</inertial>
</link>
<link name="u_neck_1_0_u_base_64">
<collision>
<origin xyz="0 0 0.003" rpy="0 -0 0" />
<geometry>
<box size="0.047 0.0275 0.006" />
</geometry>
<material name="u_neck_1_0_u_base_64_material">
<color rgba="0.301961 0.301961 0.301961 1.0"/>
</material>
</collision>
<visual>
<origin xyz="0 0 0.003" rpy="0 -0 0" />
<geometry>
<box size="0.047 0.0275 0.006" />
</geometry>
<material name="u_neck_1_0_u_base_64_material">
<color rgba="0.301961 0.301961 0.301961 1.0"/>
</material>
</visual>
<inertial>
<origin xyz="1.1674e-18 4.63685e-18 0.0024567" rpy="0 0 0"/>
<mass value="0.0169896"/>
<inertia ixx="1.47574e-06" ixy="0"  ixz="0" iyy="3.90938e-06" iyz="0" izz="5.30237e-06" />
</inertial>
</link>
<joint name="u_neck_1_u_neck_1_0_u_base_64_fixing" type="fixed">
<origin xyz="0 0 2.77556e-17" rpy="-2.57468e-31 -2.39792e-33 -4.14591e-30" />
<parent link="u_neck_1" />
<child link="u_neck_1_0_u_base_64" />
<axis xyz="0 0 0"/>
</joint>

<link name="u_neck_1_1_u_side_small">
<collision>
<origin xyz="0.015 0.023 0.0015" rpy="0 -0 0" />
<geometry>
<box size="0.025 0.044 0.003" />
</geometry>
<material name="u_neck_1_1_u_side_small_material">
<color rgba="0.301961 0.301961 0.301961 1.0"/>
</material>
</collision>
<visual>
<origin xyz="0.015 0.023 0.0015" rpy="0 -0 0" />
<geometry>
<box size="0.025 0.044 0.003" />
</geometry>
<material name="u_neck_1_1_u_side_small_material">
<color rgba="0.301961 0.301961 0.301961 1.0"/>
</material>
</visual>
<inertial>
<origin xyz="0.015 0.0221162 0.00145795" rpy="0 0 0"/>
<mass value="0.00960981"/>
<inertia ixx="1.4711e-06" ixy="1.8235e-13"  ixz="-1.13892e-14" iyy="7.29209e-07" iyz="-7.82613e-09" izz="2.1862e-06" />
</inertial>
</link>
<joint name="u_neck_1_u_neck_1_1_u_side_small_fixing" type="fixed">
<origin xyz="-0.0265 -0.015 5.55112e-17" rpy="1.5708 1.93605e-16 1.5708" />
<parent link="u_neck_1" />
<child link="u_neck_1_1_u_side_small" />
<axis xyz="0 0 0"/>
</joint>

<link name="u_neck_1_2_u_side_small">
<collision>
<origin xyz="0.015 0.023 0.0015" rpy="0 -0 0" />
<geometry>
<box size="0.025 0.044 0.003" />
</geometry>
<material name="u_neck_1_2_u_side_small_material">
<color rgba="0.301961 0.301961 0.301961 1.0"/>
</material>
</collision>
<visual>
<origin xyz="0.015 0.023 0.0015" rpy="0 -0 0" />
<geometry>
<box size="0.025 0.044 0.003" />
</geometry>
<material name="u_neck_1_2_u_side_small_material">
<color rgba="0.301961 0.301961 0.301961 1.0"/>
</material>
</visual>
<inertial>
<origin xyz="0.015 0.0221162 0.00145795" rpy="0 0 0"/>
<mass value="0.00960981"/>
<inertia ixx="1.4711e-06" ixy="1.8235e-13"  ixz="-1.13892e-14" iyy="7.29209e-07" iyz="-7.82613e-09" izz="2.1862e-06" />
</inertial>
</link>
<joint name="u_neck_1_u_neck_1_2_u_side_small_fixing" type="fixed">
<origin xyz="0.0265 0.015 8.32667e-17" rpy="1.5708 5.38345e-16 -1.5708" />
<parent link="u_neck_1" />
<child link="u_neck_1_2_u_side_small" />
<axis xyz="0 0 0"/>
</joint>

<link name="head_1">
<inertial>
<origin xyz="0 0 0" rpy="0 0 0" />
<mass value="1e-9" />
<inertia ixx="0" ixy="0" ixz="0" iyy="0" iyz="0" izz="0" />
</inertial>
</link>
<link name="head_1_0_ptgrey_fix">
<inertial>
<origin xyz="-0.000816156 3.81061e-18 0.00311579" rpy="0 0 0"/>
<mass value="0.0120467"/>
<inertia ixx="1.03243e-06" ixy="0"  ixz="-4.16285e-09" iyy="8.68613e-07" iyz="0" izz="1.81597e-06" />
</inertial>
</link>
<joint name="head_1_head_1_0_ptgrey_fix_fixing" type="fixed">
<origin xyz="0.003 -0.05455 -0.0235" rpy="1.5708 -6.93889e-16 -3.14159" />
<parent link="head_1" />
<child link="head_1_0_ptgrey_fix" />
<axis xyz="0 0 0"/>
</joint>

<link name="head_1_1_head_plate">
<collision>
<origin xyz="-0.0375 0.027 0.0015" rpy="0 -0 0" />
<geometry>
<box size="0.008 0.05 0.003" />
</geometry>
<material name="head_1_1_head_plate_material">
<color rgba="0.701961 0.682353 0.623529 1.0"/>
</material>
</collision>
<collision>
<origin xyz="0 0.027 0.0015" rpy="0 -0 0" />
<geometry>
<box size="0.008 0.05 0.003" />
</geometry>
<material name="head_1_1_head_plate_material">
<color rgba="0.701961 0.682353 0.623529 1.0"/>
</material>
</collision>
<collision>
<origin xyz="0.0375 0.027 0.0015" rpy="0 -0 0" />
<geometry>
<box size="0.008 0.05 0.003" />
</geometry>
<material name="head_1_1_head_plate_material">
<color rgba="0.701961 0.682353 0.623529 1.0"/>
</material>
</collision>
<collision>
<origin xyz="0 0.004 0.0015" rpy="0 -0 0" />
<geometry>
<box size="0.083 0.008 0.003" />
</geometry>
<material name="head_1_1_head_plate_material">
<color rgba="0.701961 0.682353 0.623529 1.0"/>
</material>
</collision>
<collision>
<origin xyz="0 0.027 0.0015" rpy="0 -0 0" />
<geometry>
<box size="0.083 0.008 0.003" />
</geometry>
<material name="head_1_1_head_plate_material">
<color rgba="0.701961 0.682353 0.623529 1.0"/>
</material>
</collision>
<collision>
<origin xyz="0 0.05 0.0015" rpy="0 -0 0" />
<geometry>
<box size="0.083 0.008 0.003" />
</geometry>
<material name="head_1_1_head_plate_material">
<color rgba="0.701961 0.682353 0.623529 1.0"/>
</material>
</collision>
<visual>
<origin xyz="-0.0375 0.027 0.0015" rpy="0 -0 0" />
<geometry>
<box size="0.008 0.05 0.003" />
</geometry>
<material name="head_1_1_head_plate_material">
<color rgba="0.701961 0.682353 0.623529 1.0"/>
</material>
</visual>
<visual>
<origin xyz="0 0.027 0.0015" rpy="0 -0 0" />
<geometry>
<box size="0.008 0.05 0.003" />
</geometry>
<material name="head_1_1_head_plate_material">
<color rgba="0.701961 0.682353 0.623529 1.0"/>
</material>
</visual>
<visual>
<origin xyz="0.0375 0.027 0.0015" rpy="0 -0 0" />
<geometry>
<box size="0.008 0.05 0.003" />
</geometry>
<material name="head_1_1_head_plate_material">
<color rgba="0.701961 0.682353 0.623529 1.0"/>
</material>
</visual>
<visual>
<origin xyz="0 0.004 0.0015" rpy="0 -0 0" />
<geometry>
<box size="0.083 0.008 0.003" />
</geometry>
<material name="head_1_1_head_plate_material">
<color rgba="0.701961 0.682353 0.623529 1.0"/>
</material>
</visual>
<visual>
<origin xyz="0 0.027 0.0015" rpy="0 -0 0" />
<geometry>
<box size="0.083 0.008 0.003" />
</geometry>
<material name="head_1_1_head_plate_material">
<color rgba="0.701961 0.682353 0.623529 1.0"/>
</material>
</visual>
<visual>
<origin xyz="0 0.05 0.0015" rpy="0 -0 0" />
<geometry>
<box size="0.083 0.008 0.003" />
</geometry>
<material name="head_1_1_head_plate_material">
<color rgba="0.701961 0.682353 0.623529 1.0"/>
</material>
</visual>
<inertial>
<origin xyz="-0.000492596 0.0229931 0.0015" rpy="0 0 0"/>
<mass value="0.0205706"/>
<inertia ixx="7.82557e-06" ixy="-7.75031e-07"  ixz="0" iyy="1.32514e-05" iyz="0" izz="2.10461e-05" />
</inertial>
</link>
<joint name="head_1_head_1_1_head_plate_fixing" type="fixed">
<origin xyz="-9.97119e-15 -0.0428 -0.0035" rpy="-3.14159 1.11022e-15 1.27635e-13" />
<parent link="head_1" />
<child link="head_1_1_head_plate" />
<axis xyz="0 0 0"/>
</joint>

<link name="head_1_2_ptgrey_camera">
<collision>
<origin xyz="0 0 0" rpy="0 -0 0" />
<geometry>
<box size="0.03 0.03 0.028" />
</geometry>
<material name="head_1_2_ptgrey_camera_material">
<color rgba="0.4 0.4 0.4 1.0"/>
</material>
</collision>
<visual>
<origin xyz="0 0 0" rpy="0 -0 0" />
<geometry>
<box size="0.03 0.03 0.028" />
</geometry>
<material name="head_1_2_ptgrey_camera_material">
<color rgba="0.4 0.4 0.4 1.0"/>
</material>
</visual>
<inertial>
<origin xyz="9.66586e-05 0.00165823 0.000186132" rpy="0 0 0"/>
<mass value="0.0277705"/>
<inertia ixx="4.44242e-06" ixy="-4.55636e-08"  ixz="-1.89678e-08" iyy="3.89154e-06" iyz="-3.70049e-08" izz="4.48389e-06" />
</inertial>
</link>
<joint name="head_1_head_1_2_ptgrey_camera_fixing" type="fixed">
<origin xyz="0.00496822 -0.06905 -0.0235" rpy="1.5708 -1.5708 0" />
<parent link="head_1" />
<child link="head_1_2_ptgrey_camera" />
<axis xyz="0 0 0"/>
</joint>

<link name="head_1_3_head_plate">
<collision>
<origin xyz="-0.0375 0.027 0.0015" rpy="0 -0 0" />
<geometry>
<box size="0.008 0.05 0.003" />
</geometry>
<material name="head_1_3_head_plate_material">
<color rgba="0.701961 0.682353 0.623529 1.0"/>
</material>
</collision>
<collision>
<origin xyz="0 0.027 0.0015" rpy="0 -0 0" />
<geometry>
<box size="0.008 0.05 0.003" />
</geometry>
<material name="head_1_3_head_plate_material">
<color rgba="0.701961 0.682353 0.623529 1.0"/>
</material>
</collision>
<collision>
<origin xyz="0.0375 0.027 0.0015" rpy="0 -0 0" />
<geometry>
<box size="0.008 0.05 0.003" />
</geometry>
<material name="head_1_3_head_plate_material">
<color rgba="0.701961 0.682353 0.623529 1.0"/>
</material>
</collision>
<collision>
<origin xyz="0 0.004 0.0015" rpy="0 -0 0" />
<geometry>
<box size="0.083 0.008 0.003" />
</geometry>
<material name="head_1_3_head_plate_material">
<color rgba="0.701961 0.682353 0.623529 1.0"/>
</material>
</collision>
<collision>
<origin xyz="0 0.027 0.0015" rpy="0 -0 0" />
<geometry>
<box size="0.083 0.008 0.003" />
</geometry>
<material name="head_1_3_head_plate_material">
<color rgba="0.701961 0.682353 0.623529 1.0"/>
</material>
</collision>
<collision>
<origin xyz="0 0.05 0.0015" rpy="0 -0 0" />
<geometry>
<box size="0.083 0.008 0.003" />
</geometry>
<material name="head_1_3_head_plate_material">
<color rgba="0.701961 0.682353 0.623529 1.0"/>
</material>
</collision>
<visual>
<origin xyz="-0.0375 0.027 0.0015" rpy="0 -0 0" />
<geometry>
<box size="0.008 0.05 0.003" />
</geometry>
<material name="head_1_3_head_plate_material">
<color rgba="0.701961 0.682353 0.623529 1.0"/>
</material>
</visual>
<visual>
<origin xyz="0 0.027 0.0015" rpy="0 -0 0" />
<geometry>
<box size="0.008 0.05 0.003" />
</geometry>
<material name="head_1_3_head_plate_material">
<color rgba="0.701961 0.682353 0.623529 1.0"/>
</material>
</visual>
<visual>
<origin xyz="0.0375 0.027 0.0015" rpy="0 -0 0" />
<geometry>
<box size="0.008 0.05 0.003" />
</geometry>
<material name="head_1_3_head_plate_material">
<color rgba="0.701961 0.682353 0.623529 1.0"/>
</material>
</visual>
<visual>
<origin xyz="0 0.004 0.0015" rpy="0 -0 0" />
<geometry>
<box size="0.083 0.008 0.003" />
</geometry>
<material name="head_1_3_head_plate_material">
<color rgba="0.701961 0.682353 0.623529 1.0"/>
</material>
</visual>
<visual>
<origin xyz="0 0.027 0.0015" rpy="0 -0 0" />
<geometry>
<box size="0.083 0.008 0.003" />
</geometry>
<material name="head_1_3_head_plate_material">
<color rgba="0.701961 0.682353 0.623529 1.0"/>
</material>
</visual>
<visual>
<origin xyz="0 0.05 0.0015" rpy="0 -0 0" />
<geometry>
<box size="0.083 0.008 0.003" />
</geometry>
<material name="head_1_3_head_plate_material">
<color rgba="0.701961 0.682353 0.623529 1.0"/>
</material>
</visual>
<inertial>
<origin xyz="-0.000492596 0.0229931 0.0015" rpy="0 0 0"/>
<mass value="0.0205706"/>
<inertia ixx="7.82557e-06" ixy="-7.75031e-07"  ixz="0" iyy="1.32514e-05" iyz="0" izz="2.10461e-05" />
</inertial>
</link>
<joint name="head_1_head_1_3_head_plate_fixing" type="fixed">
<origin xyz="-9.9018e-15 -0.0428 -0.0405" rpy="-3.14159 1.19349e-15 1.2803e-13" />
<parent link="head_1" />
<child link="head_1_3_head_plate" />
<axis xyz="0 0 0"/>
</joint>

<link name="head_1_4_mx64">
<collision>
<origin xyz="0 -0.015 0" rpy="0 -0 0" />
<geometry>
<box size="0.029 0.05 0.04" />
</geometry>
<material name="head_1_4_mx64_material">
<color rgba="0.211765 0.211765 0.211765 1.0"/>
</material>
</collision>
<visual>
<origin xyz="0 -0.015 0" rpy="0 -0 0" />
<geometry>
<box size="0.029 0.05 0.04" />
</geometry>
<material name="head_1_4_mx64_material">
<color rgba="0.211765 0.211765 0.211765 1.0"/>
</material>
</visual>
<inertial>
<origin xyz="0 0 0.00254" rpy="0 0 0"/>
<mass value="0.158"/>
<inertia ixx="7.869e-05" ixy="-8.4e-07"  ixz="4.9e-07" iyy="4.097e-05" iyz="-9.14e-06" izz="6.136e-05" />
</inertial>
</link>
<joint name="head_1_head_1_4_mx64_fixing" type="fixed">
<origin xyz="0 0 -0.0235" rpy="1.53425e-32 -5.07685e-30 -1.84267e-30" />
<parent link="head_1" />
<child link="head_1_4_mx64" />
<axis xyz="0 0 0"/>
</joint>

<link name="head_1_5_lens">
<inertial>
<origin xyz="2.16376e-19 7.05829e-19 0.00695352" rpy="0 0 0"/>
<mass value="0.00559389"/>
<inertia ixx="3.03899e-07" ixy="0"  ixz="0" iyy="3.03899e-07" iyz="0" izz="3.86538e-07" />
</inertial>
</link>
<joint name="head_1_head_1_5_lens_fixing" type="fixed">
<origin xyz="0.034233 -0.06905 -0.0235" rpy="-1.5708 -0.684656 1.5708" />
<parent link="head_1" />
<child link="head_1_5_lens" />
<axis xyz="0 0 0"/>
</joint>

<link name="camera">
<inertial>
<origin xyz="0 0 0" rpy="0 0 0" />
<mass value="1e-9" />
<inertia ixx="0" ixy="0" ixz="0" iyy="0" iyz="0" izz="0" />
</inertial>
</link>
<joint name="camera_frame" type="fixed">
<origin xyz="0.024933 -0.06905 -0.0235" rpy="-1.28343e-13 1.5708 0" />
<parent link="head_1" />
<child link="camera" />
<axis xyz="0 0 0"/>
</joint>

<joint name="head_pitch" type="revolute">
<origin xyz="-0.0235 -4.64906e-16 0.04" rpy="-1.5708 -5.38345e-16 1.5708" />
<parent link="u_neck_1" />
<child link="head_1" />
<axis xyz="0 0 1"/>
<limit effort="10" velocity="6" />
<joint_properties friction="0.0"/>
</joint>

<joint name="head_yaw" type="revolute">
<origin xyz="2.2247e-14 -0.0365 0.1858" rpy="1.12114e-14 -2.33618e-15 -3.14159" />
<parent link="trunk_1" />
<child link="u_neck_1" />
<axis xyz="-0 -0 1"/>
<limit effort="10" velocity="6" />
<joint_properties friction="0.0"/>
</joint>

</robot>
